Workbook

Sheet PANDUAN
A1: R | P | K PANDUAN SISTEM KEUANGAN | B1: R | P | K PANDUAN SISTEM KEUANGAN | C1: R | P | K PANDUAN SISTEM KEUANGAN | D1: R | P | K PANDUAN SISTEM KEUANGAN | E1: R | P | K PANDUAN SISTEM KEUANGAN | F1: R | P | K PANDUAN SISTEM KEUANGAN | G1: R | P | K PANDUAN SISTEM KEUANGAN | H1: R | P | K PANDUAN SISTEM KEUANGAN | I1: R | P | K PANDUAN SISTEM KEUANGAN
A2: R | P | K PANDUAN SISTEM KEUANGAN | B2: R | P | K PANDUAN SISTEM KEUANGAN | C2: R | P | K PANDUAN SISTEM KEUANGAN | D2: R | P | K PANDUAN SISTEM KEUANGAN | E2: R | P | K PANDUAN SISTEM KEUANGAN | F2: R | P | K PANDUAN SISTEM KEUANGAN | G2: R | P | K PANDUAN SISTEM KEUANGAN | H2: R | P | K PANDUAN SISTEM KEUANGAN | I2: R | P | K PANDUAN SISTEM KEUANGAN
A3: Panduan operasional untuk pemasukan, pengeluaran, penggajian, reimburse, piutang, kas/bank, dana klien, partner, ekuitas dan laporan manajemen. | B3: Panduan operasional untuk pemasukan, pengeluaran, penggajian, reimburse, piutang, kas/bank, dana klien, partner, ekuitas dan laporan manajemen. | C3: Panduan operasional untuk pemasukan, pengeluaran, penggajian, reimburse, piutang, kas/bank, dana klien, partner, ekuitas dan laporan manajemen. | D3: Panduan operasional untuk pemasukan, pengeluaran, penggajian, reimburse, piutang, kas/bank, dana klien, partner, ekuitas dan laporan manajemen. | E3: Panduan operasional untuk pemasukan, pengeluaran, penggajian, reimburse, piutang, kas/bank, dana klien, partner, ekuitas dan laporan manajemen. | F3: Panduan operasional untuk pemasukan, pengeluaran, penggajian, reimburse, piutang, kas/bank, dana klien, partner, ekuitas dan laporan manajemen. | G3: Panduan operasional untuk pemasukan, pengeluaran, penggajian, reimburse, piutang, kas/bank, dana klien, partner, ekuitas dan laporan manajemen. | H3: Panduan operasional untuk pemasukan, pengeluaran, penggajian, reimburse, piutang, kas/bank, dana klien, partner, ekuitas dan laporan manajemen. | I3: Panduan operasional untuk pemasukan, pengeluaran, penggajian, reimburse, piutang, kas/bank, dana klien, partner, ekuitas dan laporan manajemen.
A5: URUTAN PENCATATAN YANG DISARANKAN | B5: URUTAN PENCATATAN YANG DISARANKAN | C5: URUTAN PENCATATAN YANG DISARANKAN | D5: URUTAN PENCATATAN YANG DISARANKAN | E5: URUTAN PENCATATAN YANG DISARANKAN | F5: URUTAN PENCATATAN YANG DISARANKAN | G5: URUTAN PENCATATAN YANG DISARANKAN | H5: URUTAN PENCATATAN YANG DISARANKAN | I5: URUTAN PENCATATAN YANG DISARANKAN
A6: No. | B6: Aktivitas | C6: Cara Mencatat
A7: 01 | B7: Tetapkan master data | C7: Periksa partner, rekening, kategori biaya, periode laporan, dan parameter di MASTER.
A8: 02 | B8: Daftarkan perkara dan kontrak | C8: Isi ID perkara dan nama klien satu kali di PERKARA. Pilih ID pada sheet transaksi; nama klien terisi otomatis dan ikut berubah jika master diperbarui.
A9: 03 | B9: Terbitkan invoice | C9: Catat tagihan dan jatuh tempo pada INVOICE_PIUTANG agar piutang dapat dipantau.
A10: 04 | B10: Catat penerimaan uang | C10: Isi PEMASUKAN. Pilih jenis yang tepat: jasa hukum, reimburse, dana klien, modal, atau pinjaman.
A11: 05 | B11: Catat biaya dasar | C11: Isi PENGELUARAN satu kali dan bedakan beban Kantor, Klien, atau Partner.
A12: 06 | B12: Ajukan reimbursement | C12: Buat ID di REIMBURSE, lalu masukkan ID yang sama pada PENGELUARAN terkait.
A13: 07 | B13: Proses gaji tenaga kerja | C13: Isi GAJI untuk pegawai dan tenaga lepas; pembagian laba partner dicatat di PARTNER.
A14: 08 | B14: Pisahkan dana milik klien | C14: Setiap titipan dicatat di PEMASUKAN dan DANA_KLIEN; pembayaran klien dicatat hanya di DANA_KLIEN.
A15: 09 | B15: Catat pajak dan utang | C15: Isi KEWAJIBAN sesuai nilai nyata dan tanggal jatuh tempo; hindari menebak tarif pajak.
A16: 10 | B16: Rekonsiliasi kas dan bank | C16: Isi saldo awal serta saldo fisik/rekening di KAS_BANK; telusuri seluruh selisih.
A17: 11 | B17: Pantau anggaran dan laporan | C17: Tinjau DASHBOARD, ANGGARAN, LABA_RUGI, ARUS_KAS, dan profitabilitas per PERKARA.
A18: 12 | B18: Tutup periode dengan kontrol | C18: Buka KONTROL dan tindak lanjuti invoice jatuh tempo, bukti kurang, selisih kas, atau dana klien negatif.
A21: EMPAT PEMISAHAN YANG WAJIB DIJAGA | B21: EMPAT PEMISAHAN YANG WAJIB DIJAGA | C21: EMPAT PEMISAHAN YANG WAJIB DIJAGA | D21: EMPAT PEMISAHAN YANG WAJIB DIJAGA | E21: EMPAT PEMISAHAN YANG WAJIB DIJAGA | F21: EMPAT PEMISAHAN YANG WAJIB DIJAGA | G21: EMPAT PEMISAHAN YANG WAJIB DIJAGA | H21: EMPAT PEMISAHAN YANG WAJIB DIJAGA | I21: EMPAT PEMISAHAN YANG WAJIB DIJAGA
A22: Pendapatan jasa hukum | B22: Honorarium, retainer, success fee dan konsultasi merupakan pendapatan operasional kantor.
A23: Reimburse biaya | B23: Penggantian biaya bukan honorarium baru; pembayaran reimburse partner juga bukan biaya kedua.
A24: Dana titipan klien | B24: Dana klien merupakan kewajiban/dana terbatas, tidak boleh digunakan sebagai kas bebas kantor.
A25: Partner dan pegawai | B25: Gaji pegawai adalah beban; setoran modal, prive dan pembagian laba partner adalah transaksi ekuitas.
A28: KETERANGAN WARNA & BATASAN | B28: KETERANGAN WARNA & BATASAN | C28: KETERANGAN WARNA & BATASAN | D28: KETERANGAN WARNA & BATASAN | E28: KETERANGAN WARNA & BATASAN | F28: KETERANGAN WARNA & BATASAN | G28: KETERANGAN WARNA & BATASAN | H28: KETERANGAN WARNA & BATASAN | I28: KETERANGAN WARNA & BATASAN
A29: Krem / teks biru | B29: Sel input yang diisi atau diperbarui pengguna.
A30: Abu-abu | B30: Rumus otomatis; jangan dihapus atau ditimpa.
A31: Merah | B31: Pengecualian atau hal yang perlu ditindaklanjuti.
A32: Catatan pajak | B32: PPh, PPN dan BPJS diisi sesuai data aktual; workbook ini bukan penetapan tarif atau opini pajak.
A34: ALUR DATA YANG SALING TERHUBUNG
A35: 01 | B35: PERKARA | C35: Daftarkan ID perkara, nama klien, kontak, email, dan alamat penagihan satu kali.
A36: 02 | B36: INVOICE_PIUTANG | C36: Isi tanggal, pilih ID perkara, jenis tagihan, dan nilai. Nomor invoice, klien, jatuh tempo, piutang, dan umur tagihan terisi otomatis.
A37: 03 | B37: PEMASUKAN | C37: Pilih nomor invoice; ID perkara dan nama klien mengikuti register invoice. Masukkan tanggal, jenis penerimaan, nominal, dan akun.
A38: 04 | B38: REIMBURSE / PENGELUARAN | C38: Buat klaim dengan tanggal pengajuan; pilih ID klaim yang sama pada setiap pengeluaran terkait.
A39: 05 | B39: TRANSFER_KAS | C39: Catat perpindahan uang antar rekening di satu tempat agar tidak membuat kas/bank tidak seimbang.
A40: 06 | B40: NERACA / KONTROL | C40: Periksa saldo neraca, talangan partner, umur piutang, bukti transaksi, dan rekonsiliasi sebelum menutup bulan.
A42: PERSETUJUAN MANUAL & MEMBACA RUGI BULANAN
A43: 07 | B43: OTORISASI | C43: Periksa status, nama partner penyetuju, dan transaksi yang sudah berjalan tetapi belum mempunyai otorisasi lengkap.
A44: 08 | B44: PENGELUARAN | C44: Kolom Status Persetujuan, Nilai Disetujui, Disetujui Oleh, dan Tanggal Persetujuan diisi manual; jangan mengarang data lama.
A45: 09 | B45: REIMBURSE | C45: Setujui klaim dan setiap rincian pengeluaran secara manual; nilai disetujui baru dihitung setelah keduanya lengkap.
A46: 10 | B46: INVOICE / GAJI | C46: Nama penandatangan invoice dan slip gaji mengikuti penyetuju manual pada register sumber.
A47: 11 | B47: LABA_RUGI | C47: Bedakan rugi bulan berjalan dari laba kumulatif dan saldo kas. Dana bulan lalu bukan pemasukan bulan ini.
...

Sheet DASHBOARD
A1: R | P | K DASHBOARD KEUANGAN & ARUS KAS PARTNER | B1: R | P | K DASHBOARD KEUANGAN & ARUS KAS PARTNER | C1: R | P | K DASHBOARD KEUANGAN & ARUS KAS PARTNER | D1: R | P | K DASHBOARD KEUANGAN & ARUS KAS PARTNER | E1: R | P | K DASHBOARD KEUANGAN & ARUS KAS PARTNER | F1: R | P | K DASHBOARD KEUANGAN & ARUS KAS PARTNER | G1: R | P | K DASHBOARD KEUANGAN & ARUS KAS PARTNER | H1: R | P | K DASHBOARD KEUANGAN & ARUS KAS PARTNER | I1: R | P | K DASHBOARD KEUANGAN & ARUS KAS PARTNER | J1: R | P | K DASHBOARD KEUANGAN & ARUS KAS PARTNER | K1: R | P | K DASHBOARD KEUANGAN & ARUS KAS PARTNER | L1: R | P | K DASHBOARD KEUANGAN & ARUS KAS PARTNER | M1: R | P | K DASHBOARD KEUANGAN & ARUS KAS PARTNER | N1: R | P | K DASHBOARD KEUANGAN & ARUS KAS PARTNER
A2: R | P | K DASHBOARD KEUANGAN & ARUS KAS PARTNER | B2: R | P | K DASHBOARD KEUANGAN & ARUS KAS PARTNER | C2: R | P | K DASHBOARD KEUANGAN & ARUS KAS PARTNER | D2: R | P | K DASHBOARD KEUANGAN & ARUS KAS PARTNER | E2: R | P | K DASHBOARD KEUANGAN & ARUS KAS PARTNER | F2: R | P | K DASHBOARD KEUANGAN & ARUS KAS PARTNER | G2: R | P | K DASHBOARD KEUANGAN & ARUS KAS PARTNER | H2: R | P | K DASHBOARD KEUANGAN & ARUS KAS PARTNER | I2: R | P | K DASHBOARD KEUANGAN & ARUS KAS PARTNER | J2: R | P | K DASHBOARD KEUANGAN & ARUS KAS PARTNER | K2: R | P | K DASHBOARD KEUANGAN & ARUS KAS PARTNER | L2: R | P | K DASHBOARD KEUANGAN & ARUS KAS PARTNER | M2: R | P | K DASHBOARD KEUANGAN & ARUS KAS PARTNER | N2: R | P | K DASHBOARD KEUANGAN & ARUS KAS PARTNER
A3: Laba usaha, saldo awal, pembayaran partner, reimburse, talangan, kas akhir, dan kontrol akuntansi ditampilkan terpisah serta saling terhubung. | B3: Laba usaha, saldo awal, pembayaran partner, reimburse, talangan, kas akhir, dan kontrol akuntansi ditampilkan terpisah serta saling terhubung. | C3: Laba usaha, saldo awal, pembayaran partner, reimburse, talangan, kas akhir, dan kontrol akuntansi ditampilkan terpisah serta saling terhubung. | D3: Laba usaha, saldo awal, pembayaran partner, reimburse, talangan, kas akhir, dan kontrol akuntansi ditampilkan terpisah serta saling terhubung. | E3: Laba usaha, saldo awal, pembayaran partner, reimburse, talangan, kas akhir, dan kontrol akuntansi ditampilkan terpisah serta saling terhubung. | F3: Laba usaha, saldo awal, pembayaran partner, reimburse, talangan, kas akhir, dan kontrol akuntansi ditampilkan terpisah serta saling terhubung. | G3: Laba usaha, saldo awal, pembayaran partner, reimburse, talangan, kas akhir, dan kontrol akuntansi ditampilkan terpisah serta saling terhubung. | H3: Laba usaha, saldo awal, pembayaran partner, reimburse, talangan, kas akhir, dan kontrol akuntansi ditampilkan terpisah serta saling terhubung. | I3: Laba usaha, saldo awal, pembayaran partner, reimburse, talangan, kas akhir, dan kontrol akuntansi ditampilkan terpisah serta saling terhubung. | J3: Laba usaha, saldo awal, pembayaran partner, reimburse, talangan, kas akhir, dan kontrol akuntansi ditampilkan terpisah serta saling terhubung. | K3: Laba usaha, saldo awal, pembayaran partner, reimburse, talangan, kas akhir, dan kontrol akuntansi ditampilkan terpisah serta saling terhubung. | L3: Laba usaha, saldo awal, pembayaran partner, reimburse, talangan, kas akhir, dan kontrol akuntansi ditampilkan terpisah serta saling terhubung. | M3: Laba usaha, saldo awal, pembayaran partner, reimburse, talangan, kas akhir, dan kontrol akuntansi ditampilkan terpisah serta saling terhubung. | N3: Laba usaha, saldo awal, pembayaran partner, reimburse, talangan, kas akhir, dan kontrol akuntansi ditampilkan terpisah serta saling terhubung.
A4: Tahun Laporan | B4: =MASTER!$AF$7 -> 2026 | D4: Bulan Analisis | E4: =CHOOSE(MASTER!$AF$15,"Januari","Februari","Maret","April","Mei","Juni","Juli","Agustus","September","Oktober","November","Desember") -> Agustus | H4: =KONTROL!A68 -> PERIKSA — ADA TEMUAN KRITIS / TINGGI
A6: PENDAPATAN JASA HUKUM | B6: PENDAPATAN JASA HUKUM | C6: PENDAPATAN JASA HUKUM | D6: BEBAN OPERASIONAL | E6: BEBAN OPERASIONAL | F6: BEBAN OPERASIONAL | G6: LABA / (RUGI) OPERASIONAL | H6: LABA / (RUGI) OPERASIONAL | I6: LABA / (RUGI) OPERASIONAL | J6: LABA / (RUGI) OPERASIONAL | K6: PIUTANG KLIEN | L6: PIUTANG KLIEN | M6: PIUTANG KLIEN | N6: PIUTANG KLIEN
A7: =LABA_RUGI!N7 -> 0 | D7: =LABA_RUGI!N14 -> 0 | G7: =LABA_RUGI!N26 -> 0 | K7: =SUM(INVOICE_PIUTANG!$L$5:$L$151) -> 33500000
A10: KAS & BANK OPERASIONAL | B10: KAS & BANK OPERASIONAL | C10: KAS & BANK OPERASIONAL | D10: DANA TITIPAN KLIEN | E10: DANA TITIPAN KLIEN | F10: DANA TITIPAN KLIEN | G10: TALANGAN / UTANG PARTNER | H10: TALANGAN / UTANG PARTNER | I10: TALANGAN / UTANG PARTNER | J10: TALANGAN / UTANG PARTNER | K10: PAJAK / KEWAJIBAN TERUTANG | L10: PAJAK / KEWAJIBAN TERUTANG | M10: PAJAK / KEWAJIBAN TERUTANG | N10: PAJAK / KEWAJIBAN TERUTANG
A11: =NERACA!E6 -> 2904092 | D11: =SUM(DANA_KLIEN!$G$5:$G$154)-SUM(DANA_KLIEN!$H$5:$H$154) -> 0 | G11: =TALANGAN_PARTNER!I9 -> 1000000 | K11: =SUM(KEWAJIBAN!$G$5:$G$124) -> 3000000
A15: KINERJA BULANAN — LABA USAHA, PEMBAGIAN PARTNER, DAN PERGERAKAN KAS | B15: KINERJA BULANAN — LABA USAHA, PEMBAGIAN PARTNER, DAN PERGERAKAN KAS | C15: KINERJA BULANAN — LABA USAHA, PEMBAGIAN PARTNER, DAN PERGERAKAN KAS | D15: KINERJA BULANAN — LABA USAHA, PEMBAGIAN PARTNER, DAN PERGERAKAN KAS | E15: KINERJA BULANAN — LABA USAHA, PEMBAGIAN PARTNER, DAN PERGERAKAN KAS | F15: KINERJA BULANAN — LABA USAHA, PEMBAGIAN PARTNER, DAN PERGERAKAN KAS | G15: KINERJA BULANAN — LABA USAHA, PEMBAGIAN PARTNER, DAN PERGERAKAN KAS | H15: KINERJA BULANAN — LABA USAHA, PEMBAGIAN PARTNER, DAN PERGERAKAN KAS | I15: KINERJA BULANAN — LABA USAHA, PEMBAGIAN PARTNER, DAN PERGERAKAN KAS | J15: KINERJA BULANAN — LABA USAHA, PEMBAGIAN PARTNER, DAN PERGERAKAN KAS | K15: KINERJA BULANAN — LABA USAHA, PEMBAGIAN PARTNER, DAN PERGERAKAN KAS | L15: KINERJA BULANAN — LABA USAHA, PEMBAGIAN PARTNER, DAN PERGERAKAN KAS | M15: KINERJA BULANAN — LABA USAHA, PEMBAGIAN PARTNER, DAN PERGERAKAN KAS | N15: KINERJA BULANAN — LABA USAHA, PEMBAGIAN PARTNER, DAN PERGERAKAN KAS
A16: Bulan | B16: Pendapatan Jasa | C16: Beban Operasional | D16: Laba / (Rugi) Bulan | E16: Laba Usaha Kumulatif | F16: Kas Awal Bulan | G16: Kas Masuk Operasional | H16: Biaya + Gaji + Kewajiban | I16: Reimburse Dibayar | J16: Pembagian Partner / Prive | K16: Pengembalian Talangan | L16: Pendanaan / Mutasi Lain | M16: Kas Akhir Bulan | N16: Selisih Kontrol
A17: Jan | B17: =IF(ROW()-16>MASTER!$AF$15,"",SUMIFS(PEMASUKAN!$H$5:$H$204,PEMASUKAN!$C$5:$C$204,TEXT(DATE($B$4,ROW()-16,1),"yyyy-mm"),PEMASUKAN!$M$5:$M$204,"Pendapatan Operasional")) -> 0 | C17: =IF(ROW()-16>MASTER!$AF$15,"",SUMIFS(PENGELUARAN!$K$5:$K$204,PENGELUARAN!$C$5:$C$204,TEXT(DATE($B$4,ROW()-16,1),"yyyy-mm"),PENGELUARAN!$L$5:$L$204,"Kantor")+SUMIFS(GAJI!$Q$5:$Q$124,GAJI!$B$5:$B$124,">="&DATE($B$4,ROW()-16,1),GAJI!$B$5:$B$124,"<"&DATE($B$4,ROW()-15,1))) -> 0 | D17: =IF(ROW()-16>MASTER!$AF$15,"",B17-C17) -> 0 | E17: =IF(ROW()-16>MASTER!$AF$15,"",SUM($D$17:D17)) -> 0 | F17: =IF(ROW()-16>MASTER!$AF$15,"",IF(ROW()=17,SUMIFS(KAS_BANK!$B$5:$B$10,KAS_BANK!$A$5:$A$10,"<>Bank Dana Klien")+MAX(-KAS_BANK!$B$7,0)+MAX(-KAS_BANK!$B$8,0)+MAX(-KAS_BANK!$B$9,0),M16)) -> 0 | G17: =IF(ROW()-16>MASTER!$AF$15,"",SUMIFS(PEMASUKAN!$J$5:$J$204,PEMASUKAN!$C$5:$C$204,TEXT(DATE($B$4,ROW()-16,1),"yyyy-mm"),PEMASUKAN!$M$5:$M$204,"Pendapatan Operasional")+SUMIFS(PEMASUKAN!$J$5:$J$204,PEMASUKAN!$C$5:$C$204,TEXT(DATE($B$4,ROW()-16,1),"yyyy-mm"),PEMASUKAN!$M$5:$M$204,"Penggantian Biaya")) -> 0 | H17: =IF(ROW()-16>MASTER!$AF$15,"",SUMIFS(PENGELUARAN!$K$5:$K$204,PENGELUARAN!$C$5:$C$204,TEXT(DATE($B$4,ROW()-16,1),"yyyy-mm"),PENGELUARAN!$I$5:$I$204,"<>",PENGELUARAN!$I$5:$I$204,"<>Bank Dana Klien")+SUMIFS(GAJI!$P$5:$P$124,GAJI!$S$5:$S$124,">="&DATE($B$4,ROW()-16,1),GAJI!$S$5:$S$124,"<"&DATE($B$4,ROW()-15,1),GAJI!$R$5:$R$124,"Dibayar")+SUMIFS(KEWAJIBAN!$F$5:$F$124,KEWAJIBAN!$I$5:$I$124,">="&DATE($B$4,ROW()-16,1),KEWAJIBAN!$I$5:$I$124,"<"&DATE($B$4,ROW()-15,1))) -> 0 | I17: =IF(ROW()-16>MASTER!$AF$15,"",SUMIFS(REIMBURSE!$J$5:$J$124,REIMBURSE!$N$5:$N$124,">="&DATE($B$4,ROW()-16,1),REIMBURSE!$N$5:$N$124,"<"&DATE($B$4,ROW()-15,1))) -> 0 | J17: =IF(ROW()-16>MASTER!$AF$15,"",SUMIFS(PARTNER!$I$5:$I$124,PARTNER!$E$5:$E$124,MASTER!$Y$7,PARTNER!$V$5:$V$124,">="&DATE($B$4,ROW()-16,1),PARTNER!$V$5:$V$124,"<"&DATE($B$4,ROW()-15,1))+SUMIFS(PARTNER!$I$5:$I$124,PARTNER!$E$5:$E$124,MASTER!$Y$8,PARTNER!$V$5:$V$124,">="&DATE($B$4,ROW()-16,1),PARTNER!$V$5:$V$124,"<"&DATE($B$4,ROW()-15,1))) -> 0 | K17: =IF(ROW()-16>MASTER!$AF$15,"",SUMIFS(PARTNER!$I$5:$I$124,PARTNER!$E$5:$E$124,MASTER!$Y$9,PARTNER!$V$5:$V$124,">="&DATE($B$4,ROW()-16,1),PARTNER!$V$5:$V$124,"<"&DATE($B$4,ROW()-15,1))) -> 0 | L17: {=IF(ROW()-16>MASTER!$AF$15,"",INDEX(ARUS_KAS!$B$24:$M$24,1,ROW()-16)+INDEX(ARUS_KAS!$B$26:$M$26,1,ROW()-16)+INDEX(ARUS_KAS!$B$28:$M$28,1,ROW()-16))} -> 0 | M17: {=IF(ROW()-16>MASTER!$AF$15,"",F17+INDEX(ARUS_KAS!$B$8:$M$8,1,ROW()-16)+INDEX(ARUS_KAS!$B$9:$M$9,1,ROW()-16)-INDEX(ARUS_KAS!$B$12:$M$12,1,ROW()-16)-INDEX(ARUS_KAS!$B$13:$M$13,1,ROW()-16)-INDEX(ARUS_KAS!$B$14:$M$14,1,ROW()-16)-INDEX(ARUS_KAS!$B$15:$M$15,1,ROW()-16)+INDEX(ARUS_KAS!$B$24:$M$24,1,ROW()-16)-INDEX(ARUS_KAS!$B$25:$M$25,1,ROW()-16)+INDEX(ARUS_KAS!$B$26:$M$26,1,ROW()-16)+INDEX(ARUS_KAS!$B$28:$M$28,1,ROW()-16))} -> 0 | N17: =IF(ROW()-16>MASTER!$AF$15,"",ABS(F17+G17-H17-I17-J17-K17+L17-M17)) -> 0
A18: Feb | B18: =IF(ROW()-16>MASTER!$AF$15,"",SUMIFS(PEMASUKAN!$H$5:$H$204,PEMASUKAN!$C$5:$C$204,TEXT(DATE($B$4,ROW()-16,1),"yyyy-mm"),PEMASUKAN!$M$5:$M$204,"Pendapatan Operasional")) -> 0 | C18: =IF(ROW()-16>MASTER!$AF$15,"",SUMIFS(PENGELUARAN!$K$5:$K$204,PENGELUARAN!$C$5:$C$204,TEXT(DATE($B$4,ROW()-16,1),"yyyy-mm"),PENGELUARAN!$L$5:$L$204,"Kantor")+SUMIFS(GAJI!$Q$5:$Q$124,GAJI!$B$5:$B$124,">="&DATE($B$4,ROW()-16,1),GAJI!$B$5:$B$124,"<"&DATE($B$4,ROW()-15,1))) -> 0 | D18: =IF(ROW()-16>MASTER!$AF$15,"",B18-C18) -> 0 | E18: =IF(ROW()-16>MASTER!$AF$15,"",SUM($D$17:D18)) -> 0 | F18: =IF(ROW()-16>MASTER!$AF$15,"",IF(ROW()=17,SUMIFS(KAS_BANK!$B$5:$B$10,KAS_BANK!$A$5:$A$10,"<>Bank Dana Klien")+MAX(-KAS_BANK!$B$7,0)+MAX(-KAS_BANK!$B$8,0)+MAX(-KAS_BANK!$B$9,0),M17)) -> 0 | G18: =IF(ROW()-16>MASTER!$AF$15,"",SUMIFS(PEMASUKAN!$J$5:$J$204,PEMASUKAN!$C$5:$C$204,TEXT(DATE($B$4,ROW()-16,1),"yyyy-mm"),PEMASUKAN!$M$5:$M$204,"Pendapatan Operasional")+SUMIFS(PEMASUKAN!$J$5:$J$204,PEMASUKAN!$C$5:$C$204,TEXT(DATE($B$4,ROW()-16,1),"yyyy-mm"),PEMASUKAN!$M$5:$M$204,"Penggantian Biaya")) -> 0 | H18: =IF(ROW()-16>MASTER!$AF$15,"",SUMIFS(PENGELUARAN!$K$5:$K$204,PENGELUARAN!$C$5:$C$204,TEXT(DATE($B$4,ROW()-16,1),"yyyy-mm"),PENGELUARAN!$I$5:$I$204,"<>",PENGELUARAN!$I$5:$I$204,"<>Bank Dana Klien")+SUMIFS(GAJI!$P$5:$P$124,GAJI!$S$5:$S$124,">="&DATE($B$4,ROW()-16,1),GAJI!$S$5:$S$124,"<"&DATE($B$4,ROW()-15,1),GAJI!$R$5:$R$124,"Dibayar")+SUMIFS(KEWAJIBAN!$F$5:$F$124,KEWAJIBAN!$I$5:$I$124,">="&DATE($B$4,ROW()-16,1),KEWAJIBAN!$I$5:$I$124,"<"&DATE($B$4,ROW()-15,1))) -> 0 | I18: =IF(ROW()-16>MASTER!$AF$15,"",SUMIFS(REIMBURSE!$J$5:$J$124,REIMBURSE!$N$5:$N$124,">="&DATE($B$4,ROW()-16,1),REIMBURSE!$N$5:$N$124,"<"&DATE($B$4,ROW()-15,1))) -> 0 | J18: =IF(ROW()-16>MASTER!$AF$15,"",SUMIFS(PARTNER!$I$5:$I$124,PARTNER!$E$5:$E$124,MASTER!$Y$7,PARTNER!$V$5:$V$124,">="&DATE($B$4,ROW()-16,1),PARTNER!$V$5:$V$124,"<"&DATE($B$4,ROW()-15,1))+SUMIFS(PARTNER!$I$5:$I$124,PARTNER!$E$5:$E$124,MASTER!$Y$8,PARTNER!$V$5:$V$124,">="&DATE($B$4,ROW()-16,1),PARTNER!$V$5:$V$124,"<"&DATE($B$4,ROW()-15,1))) -> 0 | K18: =IF(ROW()-16>MASTER!$AF$15,"",SUMIFS(PARTNER!$I$5:$I$124,PARTNER!$E$5:$E$124,MASTER!$Y$9,PARTNER!$V$5:$V$124,">="&DATE($B$4,ROW()-16,1),PARTNER!$V$5:$V$124,"<"&DATE($B$4,ROW()-15,1))) -> 0 | L18: {=IF(ROW()-16>MASTER!$AF$15,"",INDEX(ARUS_KAS!$B$24:$M$24,1,ROW()-16)+INDEX(ARUS_KAS!$B$26:$M$26,1,ROW()-16)+INDEX(ARUS_KAS!$B$28:$M$28,1,ROW()-16))} -> 0 | M18: {=IF(ROW()-16>MASTER!$AF$15,"",F18+INDEX(ARUS_KAS!$B$8:$M$8,1,ROW()-16)+INDEX(ARUS_KAS!$B$9:$M$9,1,ROW()-16)-INDEX(ARUS_KAS!$B$12:$M$12,1,ROW()-16)-INDEX(ARUS_KAS!$B$13:$M$13,1,ROW()-16)-INDEX(ARUS_KAS!$B$14:$M$14,1,ROW()-16)-INDEX(ARUS_KAS!$B$15:$M$15,1,ROW()-16)+INDEX(ARUS_KAS!$B$24:$M$24,1,ROW()-16)-INDEX(ARUS_KAS!$B$25:$M$25,1,ROW()-16)+INDEX(ARUS_KAS!$B$26:$M$26,1,ROW()-16)+INDEX(ARUS_KAS!$B$28:$M$28,1,ROW()-16))} -> 0 | N18: =IF(ROW()-16>MASTER!$AF$15,"",ABS(F18+G18-H18-I18-J18-K18+L18-M18)) -> 0
A19: Mar | B19: =IF(ROW()-16>MASTER!$AF$15,"",SUMIFS(PEMASUKAN!$H$5:$H$204,PEMASUKAN!$C$5:$C$204,TEXT(DATE($B$4,ROW()-16,1),"yyyy-mm"),PEMASUKAN!$M$5:$M$204,"Pendapatan Operasional")) -> 0 | C19: =IF(ROW()-16>MASTER!$AF$15,"",SUMIFS(PENGELUARAN!$K$5:$K$204,PENGELUARAN!$C$5:$C$204,TEXT(DATE($B$4,ROW()-16,1),"yyyy-mm"),PENGELUARAN!$L$5:$L$204,"Kantor")+SUMIFS(GAJI!$Q$5:$Q$124,GAJI!$B$5:$B$124,">="&DATE($B$4,ROW()-16,1),GAJI!$B$5:$B$124,"<"&DATE($B$4,ROW()-15,1))) -> 0 | D19: =IF(ROW()-16>MASTER!$AF$15,"",B19-C19) -> 0 | E19: =IF(ROW()-16>MASTER!$AF$15,"",SUM($D$17:D19)) -> 0 | F19: =IF(ROW()-16>MASTER!$AF$15,"",IF(ROW()=17,SUMIFS(KAS_BANK!$B$5:$B$10,KAS_BANK!$A$5:$A$10,"<>Bank Dana Klien")+MAX(-KAS_BANK!$B$7,0)+MAX(-KAS_BANK!$B$8,0)+MAX(-KAS_BANK!$B$9,0),M18)) -> 0 | G19: =IF(ROW()-16>MASTER!$AF$15,"",SUMIFS(PEMASUKAN!$J$5:$J$204,PEMASUKAN!$C$5:$C$204,TEXT(DATE($B$4,ROW()-16,1),"yyyy-mm"),PEMASUKAN!$M$5:$M$204,"Pendapatan Operasional")+SUMIFS(PEMASUKAN!$J$5:$J$204,PEMASUKAN!$C$5:$C$204,TEXT(DATE($B$4,ROW()-16,1),"yyyy-mm"),PEMASUKAN!$M$5:$M$204,"Penggantian Biaya")) -> 0 | H19: =IF(ROW()-16>MASTER!$AF$15,"",SUMIFS(PENGELUARAN!$K$5:$K$204,PENGELUARAN!$C$5:$C$204,TEXT(DATE($B$4,ROW()-16,1),"yyyy-mm"),PENGELUARAN!$I$5:$I$204,"<>",PENGELUARAN!$I$5:$I$204,"<>Bank Dana Klien")+SUMIFS(GAJI!$P$5:$P$124,GAJI!$S$5:$S$124,">="&DATE($B$4,ROW()-16,1),GAJI!$S$5:$S$124,"<"&DATE($B$4,ROW()-15,1),GAJI!$R$5:$R$124,"Dibayar")+SUMIFS(KEWAJIBAN!$F$5:$F$124,KEWAJIBAN!$I$5:$I$124,">="&DATE($B$4,ROW()-16,1),KEWAJIBAN!$I$5:$I$124,"<"&DATE($B$4,ROW()-15,1))) -> 0 | I19: =IF(ROW()-16>MASTER!$AF$15,"",SUMIFS(REIMBURSE!$J$5:$J$124,REIMBURSE!$N$5:$N$124,">="&DATE($B$4,ROW()-16,1),REIMBURSE!$N$5:$N$124,"<"&DATE($B$4,ROW()-15,1))) -> 0 | J19: =IF(ROW()-16>MASTER!$AF$15,"",SUMIFS(PARTNER!$I$5:$I$124,PARTNER!$E$5:$E$124,MASTER!$Y$7,PARTNER!$V$5:$V$124,">="&DATE($B$4,ROW()-16,1),PARTNER!$V$5:$V$124,"<"&DATE($B$4,ROW()-15,1))+SUMIFS(PARTNER!$I$5:$I$124,PARTNER!$E$5:$E$124,MASTER!$Y$8,PARTNER!$V$5:$V$124,">="&DATE($B$4,ROW()-16,1),PARTNER!$V$5:$V$124,"<"&DATE($B$4,ROW()-15,1))) -> 0 | K19: =IF(ROW()-16>MASTER!$AF$15,"",SUMIFS(PARTNER!$I$5:$I$124,PARTNER!$E$5:$E$124,MASTER!$Y$9,PARTNER!$V$5:$V$124,">="&DATE($B$4,ROW()-16,1),PARTNER!$V$5:$V$124,"<"&DATE($B$4,ROW()-15,1))) -> 0 | L19: {=IF(ROW()-16>MASTER!$AF$15,"",INDEX(ARUS_KAS!$B$24:$M$24,1,ROW()-16)+INDEX(ARUS_KAS!$B$26:$M$26,1,ROW()-16)+INDEX(ARUS_KAS!$B$28:$M$28,1,ROW()-16))} -> 0 | M19: {=IF(ROW()-16>MASTER!$AF$15,"",F19+INDEX(ARUS_KAS!$B$8:$M$8,1,ROW()-16)+INDEX(ARUS_KAS!$B$9:$M$9,1,ROW()-16)-INDEX(ARUS_KAS!$B$12:$M$12,1,ROW()-16)-INDEX(ARUS_KAS!$B$13:$M$13,1,ROW()-16)-INDEX(ARUS_KAS!$B$14:$M$14,1,ROW()-16)-INDEX(ARUS_KAS!$B$15:$M$15,1,ROW()-16)+INDEX(ARUS_KAS!$B$24:$M$24,1,ROW()-16)-INDEX(ARUS_KAS!$B$25:$M$25,1,ROW()-16)+INDEX(ARUS_KAS!$B$26:$M$26,1,ROW()-16)+INDEX(ARUS_KAS!$B$28:$M$28,1,ROW()-16))} -> 0 | N19: =IF(ROW()-16>MASTER!$AF$15,"",ABS(F19+G19-H19-I19-J19-K19+L19-M19)) -> 0
A20: Apr | B20: =IF(ROW()-16>MASTER!$AF$15,"",SUMIFS(PEMASUKAN!$H$5:$H$204,PEMASUKAN!$C$5:$C$204,TEXT(DATE($B$4,ROW()-16,1),"yyyy-mm"),PEMASUKAN!$M$5:$M$204,"Pendapatan Operasional")) -> 0 | C20: =IF(ROW()-16>MASTER!$AF$15,"",SUMIFS(PENGELUARAN!$K$5:$K$204,PENGELUARAN!$C$5:$C$204,TEXT(DATE($B$4,ROW()-16,1),"yyyy-mm"),PENGELUARAN!$L$5:$L$204,"Kantor")+SUMIFS(GAJI!$Q$5:$Q$124,GAJI!$B$5:$B$124,">="&DATE($B$4,ROW()-16,1),GAJI!$B$5:$B$124,"<"&DATE($B$4,ROW()-15,1))) -> 0 | D20: =IF(ROW()-16>MASTER!$AF$15,"",B20-C20) -> 0 | E20: =IF(ROW()-16>MASTER!$AF$15,"",SUM($D$17:D20)) -> 0 | F20: =IF(ROW()-16>MASTER!$AF$15,"",IF(ROW()=17,SUMIFS(KAS_BANK!$B$5:$B$10,KAS_BANK!$A$5:$A$10,"<>Bank Dana Klien")+MAX(-KAS_BANK!$B$7,0)+MAX(-KAS_BANK!$B$8,0)+MAX(-KAS_BANK!$B$9,0),M19)) -> 0 | G20: =IF(ROW()-16>MASTER!$AF$15,"",SUMIFS(PEMASUKAN!$J$5:$J$204,PEMASUKAN!$C$5:$C$204,TEXT(DATE($B$4,ROW()-16,1),"yyyy-mm"),PEMASUKAN!$M$5:$M$204,"Pendapatan Operasional")+SUMIFS(PEMASUKAN!$J$5:$J$204,PEMASUKAN!$C$5:$C$204,TEXT(DATE($B$4,ROW()-16,1),"yyyy-mm"),PEMASUKAN!$M$5:$M$204,"Penggantian Biaya")) -> 0 | H20: =IF(ROW()-16>MASTER!$AF$15,"",SUMIFS(PENGELUARAN!$K$5:$K$204,PENGELUARAN!$C$5:$C$204,TEXT(DATE($B$4,ROW()-16,1),"yyyy-mm"),PENGELUARAN!$I$5:$I$204,"<>",PENGELUARAN!$I$5:$I$204,"<>Bank Dana Klien")+SUMIFS(GAJI!$P$5:$P$124,GAJI!$S$5:$S$124,">="&DATE($B$4,ROW()-16,1),GAJI!$S$5:$S$124,"<"&DATE($B$4,ROW()-15,1),GAJI!$R$5:$R$124,"Dibayar")+SUMIFS(KEWAJIBAN!$F$5:$F$124,KEWAJIBAN!$I$5:$I$124,">="&DATE($B$4,ROW()-16,1),KEWAJIBAN!$I$5:$I$124,"<"&DATE($B$4,ROW()-15,1))) -> 0 | I20: =IF(ROW()-16>MASTER!$AF$15,"",SUMIFS(REIMBURSE!$J$5:$J$124,REIMBURSE!$N$5:$N$124,">="&DATE($B$4,ROW()-16,1),REIMBURSE!$N$5:$N$124,"<"&DATE($B$4,ROW()-15,1))) -> 0 | J20: =IF(ROW()-16>MASTER!$AF$15,"",SUMIFS(PARTNER!$I$5:$I$124,PARTNER!$E$5:$E$124,MASTER!$Y$7,PARTNER!$V$5:$V$124,">="&DATE($B$4,ROW()-16,1),PARTNER!$V$5:$V$124,"<"&DATE($B$4,ROW()-15,1))+SUMIFS(PARTNER!$I$5:$I$124,PARTNER!$E$5:$E$124,MASTER!$Y$8,PARTNER!$V$5:$V$124,">="&DATE($B$4,ROW()-16,1),PARTNER!$V$5:$V$124,"<"&DATE($B$4,ROW()-15,1))) -> 0 | K20: =IF(ROW()-16>MASTER!$AF$15,"",SUMIFS(PARTNER!$I$5:$I$124,PARTNER!$E$5:$E$124,MASTER!$Y$9,PARTNER!$V$5:$V$124,">="&DATE($B$4,ROW()-16,1),PARTNER!$V$5:$V$124,"<"&DATE($B$4,ROW()-15,1))) -> 0 | L20: {=IF(ROW()-16>MASTER!$AF$15,"",INDEX(ARUS_KAS!$B$24:$M$24,1,ROW()-16)+INDEX(ARUS_KAS!$B$26:$M$26,1,ROW()-16)+INDEX(ARUS_KAS!$B$28:$M$28,1,ROW()-16))} -> 0 | M20: {=IF(ROW()-16>MASTER!$AF$15,"",F20+INDEX(ARUS_KAS!$B$8:$M$8,1,ROW()-16)+INDEX(ARUS_KAS!$B$9:$M$9,1,ROW()-16)-INDEX(ARUS_KAS!$B$12:$M$12,1,ROW()-16)-INDEX(ARUS_KAS!$B$13:$M$13,1,ROW()-16)-INDEX(ARUS_KAS!$B$14:$M$14,1,ROW()-16)-INDEX(ARUS_KAS!$B$15:$M$15,1,ROW()-16)+INDEX(ARUS_KAS!$B$24:$M$24,1,ROW()-16)-INDEX(ARUS_KAS!$B$25:$M$25,1,ROW()-16)+INDEX(ARUS_KAS!$B$26:$M$26,1,ROW()-16)+INDEX(ARUS_KAS!$B$28:$M$28,1,ROW()-16))} -> 0 | N20: =IF(ROW()-16>MASTER!$AF$15,"",ABS(F20+G20-H20-I20-J20-K20+L20-M20)) -> 0
A21: Mei | B21: =IF(ROW()-16>MASTER!$AF$15,"",SUMIFS(PEMASUKAN!$H$5:$H$204,PEMASUKAN!$C$5:$C$204,TEXT(DATE($B$4,ROW()-16,1),"yyyy-mm"),PEMASUKAN!$M$5:$M$204,"Pendapatan Operasional")) -> 0 | C21: =IF(ROW()-16>MASTER!$AF$15,"",SUMIFS(PENGELUARAN!$K$5:$K$204,PENGELUARAN!$C$5:$C$204,TEXT(DATE($B$4,ROW()-16,1),"yyyy-mm"),PENGELUARAN!$L$5:$L$204,"Kantor")+SUMIFS(GAJI!$Q$5:$Q$124,GAJI!$B$5:$B$124,">="&DATE($B$4,ROW()-16,1),GAJI!$B$5:$B$124,"<"&DATE($B$4,ROW()-15,1))) -> 0 | D21: =IF(ROW()-16>MASTER!$AF$15,"",B21-C21) -> 0 | E21: =IF(ROW()-16>MASTER!$AF$15,"",SUM($D$17:D21)) -> 0 | F21: =IF(ROW()-16>MASTER!$AF$15,"",IF(ROW()=17,SUMIFS(KAS_BANK!$B$5:$B$10,KAS_BANK!$A$5:$A$10,"<>Bank Dana Klien")+MAX(-KAS_BANK!$B$7,0)+MAX(-KAS_BANK!$B$8,0)+MAX(-KAS_BANK!$B$9,0),M20)) -> 0 | G21: =IF(ROW()-16>MASTER!$AF$15,"",SUMIFS(PEMASUKAN!$J$5:$J$204,PEMASUKAN!$C$5:$C$204,TEXT(DATE($B$4,ROW()-16,1),"yyyy-mm"),PEMASUKAN!$M$5:$M$204,"Pendapatan Operasional")+SUMIFS(PEMASUKAN!$J$5:$J$204,PEMASUKAN!$C$5:$C$204,TEXT(DATE($B$4,ROW()-16,1),"yyyy-mm"),PEMASUKAN!$M$5:$M$204,"Penggantian Biaya")) -> 0 | H21: =IF(ROW()-16>MASTER!$AF$15,"",SUMIFS(PENGELUARAN!$K$5:$K$204,PENGELUARAN!$C$5:$C$204,TEXT(DATE($B$4,ROW()-16,1),"yyyy-mm"),PENGELUARAN!$I$5:$I$204,"<>",PENGELUARAN!$I$5:$I$204,"<>Bank Dana Klien")+SUMIFS(GAJI!$P$5:$P$124,GAJI!$S$5:$S$124,">="&DATE($B$4,ROW()-16,1),GAJI!$S$5:$S$124,"<"&DATE($B$4,ROW()-15,1),GAJI!$R$5:$R$124,"Dibayar")+SUMIFS(KEWAJIBAN!$F$5:$F$124,KEWAJIBAN!$I$5:$I$124,">="&DATE($B$4,ROW()-16,1),KEWAJIBAN!$I$5:$I$124,"<"&DATE($B$4,ROW()-15,1))) -> 0 | I21: =IF(ROW()-16>MASTER!$AF$15,"",SUMIFS(REIMBURSE!$J$5:$J$124,REIMBURSE!$N$5:$N$124,">="&DATE($B$4,ROW()-16,1),REIMBURSE!$N$5:$N$124,"<"&DATE($B$4,ROW()-15,1))) -> 0 | J21: =IF(ROW()-16>MASTER!$AF$15,"",SUMIFS(PARTNER!$I$5:$I$124,PARTNER!$E$5:$E$124,MASTER!$Y$7,PARTNER!$V$5:$V$124,">="&DATE($B$4,ROW()-16,1),PARTNER!$V$5:$V$124,"<"&DATE($B$4,ROW()-15,1))+SUMIFS(PARTNER!$I$5:$I$124,PARTNER!$E$5:$E$124,MASTER!$Y$8,PARTNER!$V$5:$V$124,">="&DATE($B$4,ROW()-16,1),PARTNER!$V$5:$V$124,"<"&DATE($B$4,ROW()-15,1))) -> 0 | K21: =IF(ROW()-16>MASTER!$AF$15,"",SUMIFS(PARTNER!$I$5:$I$124,PARTNER!$E$5:$E$124,MASTER!$Y$9,PARTNER!$V$5:$V$124,">="&DATE($B$4,ROW()-16,1),PARTNER!$V$5:$V$124,"<"&DATE($B$4,ROW()-15,1))) -> 0 | L21: {=IF(ROW()-16>MASTER!$AF$15,"",INDEX(ARUS_KAS!$B$24:$M$24,1,ROW()-16)+INDEX(ARUS_KAS!$B$26:$M$26,1,ROW()-16)+INDEX(ARUS_KAS!$B$28:$M$28,1,ROW()-16))} -> 0 | M21: {=IF(ROW()-16>MASTER!$AF$15,"",F21+INDEX(ARUS_KAS!$B$8:$M$8,1,ROW()-16)+INDEX(ARUS_KAS!$B$9:$M$9,1,ROW()-16)-INDEX(ARUS_KAS!$B$12:$M$12,1,ROW()-16)-INDEX(ARUS_KAS!$B$13:$M$13,1,ROW()-16)-INDEX(ARUS_KAS!$B$14:$M$14,1,ROW()-16)-INDEX(ARUS_KAS!$B$15:$M$15,1,ROW()-16)+INDEX(ARUS_KAS!$B$24:$M$24,1,ROW()-16)-INDEX(ARUS_KAS!$B$25:$M$25,1,ROW()-16)+INDEX(ARUS_KAS!$B$26:$M$26,1,ROW()-16)+INDEX(ARUS_KAS!$B$28:$M$28,1,ROW()-16))} -> 0 | N21: =IF(ROW()-16>MASTER!$AF$15,"",ABS(F21+G21-H21-I21-J21-K21+L21-M21)) -> 0
A22: Jun | B22: =IF(ROW()-16>MASTER!$AF$15,"",SUMIFS(PEMASUKAN!$H$5:$H$204,PEMASUKAN!$C$5:$C$204,TEXT(DATE($B$4,ROW()-16,1),"yyyy-mm"),PEMASUKAN!$M$5:$M$204,"Pendapatan Operasional")) -> 0 | C22: =IF(ROW()-16>MASTER!$AF$15,"",SUMIFS(PENGELUARAN!$K$5:$K$204,PENGELUARAN!$C$5:$C$204,TEXT(DATE($B$4,ROW()-16,1),"yyyy-mm"),PENGELUARAN!$L$5:$L$204,"Kantor")+SUMIFS(GAJI!$Q$5:$Q$124,GAJI!$B$5:$B$124,">="&DATE($B$4,ROW()-16,1),GAJI!$B$5:$B$124,"<"&DATE($B$4,ROW()-15,1))) -> 0 | D22: =IF(ROW()-16>MASTER!$AF$15,"",B22-C22) -> 0 | E22: =IF(ROW()-16>MASTER!$AF$15,"",SUM($D$17:D22)) -> 0 | F22: =IF(ROW()-16>MASTER!$AF$15,"",IF(ROW()=17,SUMIFS(KAS_BANK!$B$5:$B$10,KAS_BANK!$A$5:$A$10,"<>Bank Dana Klien")+MAX(-KAS_BANK!$B$7,0)+MAX(-KAS_BANK!$B$8,0)+MAX(-KAS_BANK!$B$9,0),M21)) -> 0 | G22: =IF(ROW()-16>MASTER!$AF$15,"",SUMIFS(PEMASUKAN!$J$5:$J$204,PEMASUKAN!$C$5:$C$204,TEXT(DATE($B$4,ROW()-16,1),"yyyy-mm"),PEMASUKAN!$M$5:$M$204,"Pendapatan Operasional")+SUMIFS(PEMASUKAN!$J$5:$J$204,PEMASUKAN!$C$5:$C$204,TEXT(DATE($B$4,ROW()-16,1),"yyyy-mm"),PEMASUKAN!$M$5:$M$204,"Penggantian Biaya")) -> 0 | H22: =IF(ROW()-16>MASTER!$AF$15,"",SUMIFS(PENGELUARAN!$K$5:$K$204,PENGELUARAN!$C$5:$C$204,TEXT(DATE($B$4,ROW()-16,1),"yyyy-mm"),PENGELUARAN!$I$5:$I$204,"<>",PENGELUARAN!$I$5:$I$204,"<>Bank Dana Klien")+SUMIFS(GAJI!$P$5:$P$124,GAJI!$S$5:$S$124,">="&DATE($B$4,ROW()-16,1),GAJI!$S$5:$S$124,"<"&DATE($B$4,ROW()-15,1),GAJI!$R$5:$R$124,"Dibayar")+SUMIFS(KEWAJIBAN!$F$5:$F$124,KEWAJIBAN!$I$5:$I$124,">="&DATE($B$4,ROW()-16,1),KEWAJIBAN!$I$5:$I$124,"<"&DATE($B$4,ROW()-15,1))) -> 0 | I22: =IF(ROW()-16>MASTER!$AF$15,"",SUMIFS(REIMBURSE!$J$5:$J$124,REIMBURSE!$N$5:$N$124,">="&DATE($B$4,ROW()-16,1),REIMBURSE!$N$5:$N$124,"<"&DATE($B$4,ROW()-15,1))) -> 0 | J22: =IF(ROW()-16>MASTER!$AF$15,"",SUMIFS(PARTNER!$I$5:$I$124,PARTNER!$E$5:$E$124,MASTER!$Y$7,PARTNER!$V$5:$V$124,">="&DATE($B$4,ROW()-16,1),PARTNER!$V$5:$V$124,"<"&DATE($B$4,ROW()-15,1))+SUMIFS(PARTNER!$I$5:$I$124,PARTNER!$E$5:$E$124,MASTER!$Y$8,PARTNER!$V$5:$V$124,">="&DATE($B$4,ROW()-16,1),PARTNER!$V$5:$V$124,"<"&DATE($B$4,ROW()-15,1))) -> 0 | K22: =IF(ROW()-16>MASTER!$AF$15,"",SUMIFS(PARTNER!$I$5:$I$124,PARTNER!$E$5:$E$124,MASTER!$Y$9,PARTNER!$V$5:$V$124,">="&DATE($B$4,ROW()-16,1),PARTNER!$V$5:$V$124,"<"&DATE($B$4,ROW()-15,1))) -> 0 | L22: {=IF(ROW()-16>MASTER!$AF$15,"",INDEX(ARUS_KAS!$B$24:$M$24,1,ROW()-16)+INDEX(ARUS_KAS!$B$26:$M$26,1,ROW()-16)+INDEX(ARUS_KAS!$B$28:$M$28,1,ROW()-16))} -> 0 | M22: {=IF(ROW()-16>MASTER!$AF$15,"",F22+INDEX(ARUS_KAS!$B$8:$M$8,1,ROW()-16)+INDEX(ARUS_KAS!$B$9:$M$9,1,ROW()-16)-INDEX(ARUS_KAS!$B$12:$M$12,1,ROW()-16)-INDEX(ARUS_KAS!$B$13:$M$13,1,ROW()-16)-INDEX(ARUS_KAS!$B$14:$M$14,1,ROW()-16)-INDEX(ARUS_KAS!$B$15:$M$15,1,ROW()-16)+INDEX(ARUS_KAS!$B$24:$M$24,1,ROW()-16)-INDEX(ARUS_KAS!$B$25:$M$25,1,ROW()-16)+INDEX(ARUS_KAS!$B$26:$M$26,1,ROW()-16)+INDEX(ARUS_KAS!$B$28:$M$28,1,ROW()-16))} -> 0 | N22: =IF(ROW()-16>MASTER!$AF$15,"",ABS(F22+G22-H22-I22-J22-K22+L22-M22)) -> 0
A23: Jul | B23: =IF(ROW()-16>MASTER!$AF$15,"",SUMIFS(PEMASUKAN!$H$5:$H$204,PEMASUKAN!$C$5:$C$204,TEXT(DATE($B$4,ROW()-16,1),"yyyy-mm"),PEMASUKAN!$M$5:$M$204,"Pendapatan Operasional")) -> 16000000 | C23: =IF(ROW()-16>MASTER!$AF$15,"",SUMIFS(PENGELUARAN!$K$5:$K$204,PENGELUARAN!$C$5:$C$204,TEXT(DATE($B$4,ROW()-16,1),"yyyy-mm"),PENGELUARAN!$L$5:$L$204,"Kantor")+SUMIFS(GAJI!$Q$5:$Q$124,GAJI!$B$5:$B$124,">="&DATE($B$4,ROW()-16,1),GAJI!$B$5:$B$124,"<"&DATE($B$4,ROW()-15,1))) -> 3390600 | D23: =IF(ROW()-16>MASTER!$AF$15,"",B23-C23) -> 12609400 | E23: =IF(ROW()-16>MASTER!$AF$15,"",SUM($D$17:D23)) -> 12609400 | F23: =IF(ROW()-16>MASTER!$AF$15,"",IF(ROW()=17,SUMIFS(KAS_BANK!$B$5:$B$10,KAS_BANK!$A$5:$A$10,"<>Bank Dana Klien")+MAX(-KAS_BANK!$B$7,0)+MAX(-KAS_BANK!$B$8,0)+MAX(-KAS_BANK!$B$9,0),M22)) -> 0 | G23: =IF(ROW()-16>MASTER!$AF$15,"",SUMIFS(PEMASUKAN!$J$5:$J$204,PEMASUKAN!$C$5:$C$204,TEXT(DATE($B$4,ROW()-16,1),"yyyy-mm"),PEMASUKAN!$M$5:$M$204,"Pendapatan Operasional")+SUMIFS(PEMASUKAN!$J$5:$J$204,PEMASUKAN!$C$5:$C$204,TEXT(DATE($B$4,ROW()-16,1),"yyyy-mm"),PEMASUKAN!$M$5:$M$204,"Penggantian Biaya")) -> 16000000 | H23: =IF(ROW()-16>MASTER!$AF$15,"",SUMIFS(PENGELUARAN!$K$5:$K$204,PENGELUARAN!$C$5:$C$204,TEXT(DATE($B$4,ROW()-16,1),"yyyy-mm"),PENGELUARAN!$I$5:$I$204,"<>",PENGELUARAN!$I$5:$I$204,"<>Bank Dana Klien")+SUMIFS(GAJI!$P$5:$P$124,GAJI!$S$5:$S$124,">="&DATE($B$4,ROW()-16,1),GAJI!$S$5:$S$124,"<"&DATE($B$4,ROW()-15,1),GAJI!$R$5:$R$124,"Dibayar")+SUMIFS(KEWAJIBAN!$F$5:$F$124,KEWAJIBAN!$I$5:$I$124,">="&DATE($B$4,ROW()-16,1),KEWAJIBAN!$I$5:$I$124,"<"&DATE($B$4,ROW()-15,1))) -> 3390600 | I23: =IF(ROW()-16>MASTER!$AF$15,"",SUMIFS(REIMBURSE!$J$5:$J$124,REIMBURSE!$N$5:$N$124,">="&DATE($B$4,ROW()-16,1),REIMBURSE!$N$5:$N$124,"<"&DATE($B$4,ROW()-15,1))) -> 0 | J23: =IF(ROW()-16>MASTER!$AF$15,"",SUMIFS(PARTNER!$I$5:$I$124,PARTNER!$E$5:$E$124,MASTER!$Y$7,PARTNER!$V$5:$V$124,">="&DATE($B$4,ROW()-16,1),PARTNER!$V$5:$V$124,"<"&DATE($B$4,ROW()-15,1))+SUMIFS(PARTNER!$I$5:$I$124,PARTNER!$E$5:$E$124,MASTER!$Y$8,PARTNER!$V$5:$V$124,">="&DATE($B$4,ROW()-16,1),PARTNER!$V$5:$V$124,"<"&DATE($B$4,ROW()-15,1))) -> 9000000 | K23: =IF(ROW()-16>MASTER!$AF$15,"",SUMIFS(PARTNER!$I$5:$I$124,PARTNER!$E$5:$E$124,MASTER!$Y$9,PARTNER!$V$5:$V$124,">="&DATE($B$4,ROW()-16,1),PARTNER!$V$5:$V$124,"<"&DATE($B$4,ROW()-15,1))) -> 0 | L23: {=IF(ROW()-16>MASTER!$AF$15,"",INDEX(ARUS_KAS!$B$24:$M$24,1,ROW()-16)+INDEX(ARUS_KAS!$B$26:$M$26,1,ROW()-16)+INDEX(ARUS_KAS!$B$28:$M$28,1,ROW()-16))} -> 1000000 | M23: {=IF(ROW()-16>MASTER!$AF$15,"",F23+INDEX(ARUS_KAS!$B$8:$M$8,1,ROW()-16)+INDEX(ARUS_KAS!$B$9:$M$9,1,ROW()-16)-INDEX(ARUS_KAS!$B$12:$M$12,1,ROW()-16)-INDEX(ARUS_KAS!$B$13:$M$13,1,ROW()-16)-INDEX(ARUS_KAS!$B$14:$M$14,1,ROW()-16)-INDEX(ARUS_KAS!$B$15:$M$15,1,ROW()-16)+INDEX(ARUS_KAS!$B$24:$M$24,1,ROW()-16)-INDEX(ARUS_KAS!$B$25:$M$25,1,ROW()-16)+INDEX(ARUS_KAS!$B$26:$M$26,1,ROW()-16)+INDEX(ARUS_KAS!$B$28:$M$28,1,ROW()-16))} -> 4609400 | N23: =IF(ROW()-16>MASTER!$AF$15,"",ABS(F23+G23-H23-I23-J23-K23+L23-M23)) -> 0
A24: Agu | B24: =IF(ROW()-16>MASTER!$AF$15,"",SUMIFS(PEMASUKAN!$H$5:$H$204,PEMASUKAN!$C$5:$C$204,TEXT(DATE($B$4,ROW()-16,1),"yyyy-mm"),PEMASUKAN!$M$5:$M$204,"Pendapatan Operasional")) -> 0 | C24: =IF(ROW()-16>MASTER!$AF$15,"",SUMIFS(PENGELUARAN!$K$5:$K$204,PENGELUARAN!$C$5:$C$204,TEXT(DATE($B$4,ROW()-16,1),"yyyy-mm"),PENGELUARAN!$L$5:$L$204,"Kantor")+SUMIFS(GAJI!$Q$5:$Q$124,GAJI!$B$5:$B$124,">="&DATE($B$4,ROW()-16,1),GAJI!$B$5:$B$124,"<"&DATE($B$4,ROW()-15,1))) -> 4705308 | D24: =IF(ROW()-16>MASTER!$AF$15,"",B24-C24) -> -4705308 | E24: =IF(ROW()-16>MASTER!$AF$15,"",SUM($D$17:D24)) -> 7904092 | F24: =IF(ROW()-16>MASTER!$AF$15,"",IF(ROW()=17,SUMIFS(KAS_BANK!$B$5:$B$10,KAS_BANK!$A$5:$A$10,"<>Bank Dana Klien")+MAX(-KAS_BANK!$B$7,0)+MAX(-KAS_BANK!$B$8,0)+MAX(-KAS_BANK!$B$9,0),M23)) -> 4609400 | G24: =IF(ROW()-16>MASTER!$AF$15,"",SUMIFS(PEMASUKAN!$J$5:$J$204,PEMASUKAN!$C$5:$C$204,TEXT(DATE($B$4,ROW()-16,1),"yyyy-mm"),PEMASUKAN!$M$5:$M$204,"Pendapatan Operasional")+SUMIFS(PEMASUKAN!$J$5:$J$204,PEMASUKAN!$C$5:$C$204,TEXT(DATE($B$4,ROW()-16,1),"yyyy-mm"),PEMASUKAN!$M$5:$M$204,"Penggantian Biaya")) -> 0 | H24: =IF(ROW()-16>MASTER!$AF$15,"",SUMIFS(PENGELUARAN!$K$5:$K$204,PENGELUARAN!$C$5:$C$204,TEXT(DATE($B$4,ROW()-16,1),"yyyy-mm"),PENGELUARAN!$I$5:$I$204,"<>",PENGELUARAN!$I$5:$I$204,"<>Bank Dana Klien")+SUMIFS(GAJI!$P$5:$P$124,GAJI!$S$5:$S$124,">="&DATE($B$4,ROW()-16,1),GAJI!$S$5:$S$124,"<"&DATE($B$4,ROW()-15,1),GAJI!$R$5:$R$124,"Dibayar")+SUMIFS(KEWAJIBAN!$F$5:$F$124,KEWAJIBAN!$I$5:$I$124,">="&DATE($B$4,ROW()-16,1),KEWAJIBAN!$I$5:$I$124,"<"&DATE($B$4,ROW()-15,1))) -> 1705308 | I24: =IF(ROW()-16>MASTER!$AF$15,"",SUMIFS(REIMBURSE!$J$5:$J$124,REIMBURSE!$N$5:$N$124,">="&DATE($B$4,ROW()-16,1),REIMBURSE!$N$5:$N$124,"<"&DATE($B$4,ROW()-15,1))) -> 0 | J24: =IF(ROW()-16>MASTER!$AF$15,"",SUMIFS(PARTNER!$I$5:$I$124,PARTNER!$E$5:$E$124,MASTER!$Y$7,PARTNER!$V$5:$V$124,">="&DATE($B$4,ROW()-16,1),PARTNER!$V$5:$V$124,"<"&DATE($B$4,ROW()-15,1))+SUMIFS(PARTNER!$I$5:$I$124,PARTNER!$E$5:$E$124,MASTER!$Y$8,PARTNER!$V$5:$V$124,">="&DATE($B$4,ROW()-16,1),PARTNER!$V$5:$V$124,"<"&DATE($B$4,ROW()-15,1))) -> 0 | K24: =IF(ROW()-16>MASTER!$AF$15,"",SUMIFS(PARTNER!$I$5:$I$124,PARTNER!$E$5:$E$124,MASTER!$Y$9,PARTNER!$V$5:$V$124,">="&DATE($B$4,ROW()-16,1),PARTNER!$V$5:$V$124,"<"&DATE($B$4,ROW()-15,1))) -> 0 | L24: {=IF(ROW()-16>MASTER!$AF$15,"",INDEX(ARUS_KAS!$B$24:$M$24,1,ROW()-16)+INDEX(ARUS_KAS!$B$26:$M$26,1,ROW()-16)+INDEX(ARUS_KAS!$B$28:$M$28,1,ROW()-16))} -> 0 | M24: {=IF(ROW()-16>MASTER!$AF$15,"",F24+INDEX(ARUS_KAS!$B$8:$M$8,1,ROW()-16)+INDEX(ARUS_KAS!$B$9:$M$9,1,ROW()-16)-INDEX(ARUS_KAS!$B$12:$M$12,1,ROW()-16)-INDEX(ARUS_KAS!$B$13:$M$13,1,ROW()-16)-INDEX(ARUS_KAS!$B$14:$M$14,1,ROW()-16)-INDEX(ARUS_KAS!$B$15:$M$15,1,ROW()-16)+INDEX(ARUS_KAS!$B$24:$M$24,1,ROW()-16)-INDEX(ARUS_KAS!$B$25:$M$25,1,ROW()-16)+INDEX(ARUS_KAS!$B$26:$M$26,1,ROW()-16)+INDEX(ARUS_KAS!$B$28:$M$28,1,ROW()-16))} -> 2904092 | N24: =IF(ROW()-16>MASTER!$AF$15,"",ABS(F24+G24-H24-I24-J24-K24+L24-M24)) -> 0
A25: Sep | B25: =IF(ROW()-16>MASTER!$AF$15,"",SUMIFS(PEMASUKAN!$H$5:$H$204,PEMASUKAN!$C$5:$C$204,TEXT(DATE($B$4,ROW()-16,1),"yyyy-mm"),PEMASUKAN!$M$5:$M$204,"Pendapatan Operasional")) | C25: =IF(ROW()-16>MASTER!$AF$15,"",SUMIFS(PENGELUARAN!$K$5:$K$204,PENGELUARAN!$C$5:$C$204,TEXT(DATE($B$4,ROW()-16,1),"yyyy-mm"),PENGELUARAN!$L$5:$L$204,"Kantor")+SUMIFS(GAJI!$Q$5:$Q$124,GAJI!$B$5:$B$124,">="&DATE($B$4,ROW()-16,1),GAJI!$B$5:$B$124,"<"&DATE($B$4,ROW()-15,1))) | D25: =IF(ROW()-16>MASTER!$AF$15,"",B25-C25) | E25: =IF(ROW()-16>MASTER!$AF$15,"",SUM($D$17:D25)) | F25: =IF(ROW()-16>MASTER!$AF$15,"",IF(ROW()=17,SUMIFS(KAS_BANK!$B$5:$B$10,KAS_BANK!$A$5:$A$10,"<>Bank Dana Klien")+MAX(-KAS_BANK!$B$7,0)+MAX(-KAS_BANK!$B$8,0)+MAX(-KAS_BANK!$B$9,0),M24)) | G25: =IF(ROW()-16>MASTER!$AF$15,"",SUMIFS(PEMASUKAN!$J$5:$J$204,PEMASUKAN!$C$5:$C$204,TEXT(DATE($B$4,ROW()-16,1),"yyyy-mm"),PEMASUKAN!$M$5:$M$204,"Pendapatan Operasional")+SUMIFS(PEMASUKAN!$J$5:$J$204,PEMASUKAN!$C$5:$C$204,TEXT(DATE($B$4,ROW()-16,1),"yyyy-mm"),PEMASUKAN!$M$5:$M$204,"Penggantian Biaya")) | H25: =IF(ROW()-16>MASTER!$AF$15,"",SUMIFS(PENGELUARAN!$K$5:$K$204,PENGELUARAN!$C$5:$C$204,TEXT(DATE($B$4,ROW()-16,1),"yyyy-mm"),PENGELUARAN!$I$5:$I$204,"<>",PENGELUARAN!$I$5:$I$204,"<>Bank Dana Klien")+SUMIFS(GAJI!$P$5:$P$124,GAJI!$S$5:$S$124,">="&DATE($B$4,ROW()-16,1),GAJI!$S$5:$S$124,"<"&DATE($B$4,ROW()-15,1),GAJI!$R$5:$R$124,"Dibayar")+SUMIFS(KEWAJIBAN!$F$5:$F$124,KEWAJIBAN!$I$5:$I$124,">="&DATE($B$4,ROW()-16,1),KEWAJIBAN!$I$5:$I$124,"<"&DATE($B$4,ROW()-15,1))) | I25: =IF(ROW()-16>MASTER!$AF$15,"",SUMIFS(REIMBURSE!$J$5:$J$124,REIMBURSE!$N$5:$N$124,">="&DATE($B$4,ROW()-16,1),REIMBURSE!$N$5:$N$124,"<"&DATE($B$4,ROW()-15,1))) | J25: =IF(ROW()-16>MASTER!$AF$15,"",SUMIFS(PARTNER!$I$5:$I$124,PARTNER!$E$5:$E$124,MASTER!$Y$7,PARTNER!$V$5:$V$124,">="&DATE($B$4,ROW()-16,1),PARTNER!$V$5:$V$124,"<"&DATE($B$4,ROW()-15,1))+SUMIFS(PARTNER!$I$5:$I$124,PARTNER!$E$5:$E$124,MASTER!$Y$8,PARTNER!$V$5:$V$124,">="&DATE($B$4,ROW()-16,1),PARTNER!$V$5:$V$124,"<"&DATE($B$4,ROW()-15,1))) | K25: =IF(ROW()-16>MASTER!$AF$15,"",SUMIFS(PARTNER!$I$5:$I$124,PARTNER!$E$5:$E$124,MASTER!$Y$9,PARTNER!$V$5:$V$124,">="&DATE($B$4,ROW()-16,1),PARTNER!$V$5:$V$124,"<"&DATE($B$4,ROW()-15,1))) | L25: {=IF(ROW()-16>MASTER!$AF$15,"",INDEX(ARUS_KAS!$B$24:$M$24,1,ROW()-16)+INDEX(ARUS_KAS!$B$26:$M$26,1,ROW()-16)+INDEX(ARUS_KAS!$B$28:$M$28,1,ROW()-16))} | M25: {=IF(ROW()-16>MASTER!$AF$15,"",F25+INDEX(ARUS_KAS!$B$8:$M$8,1,ROW()-16)+INDEX(ARUS_KAS!$B$9:$M$9,1,ROW()-16)-INDEX(ARUS_KAS!$B$12:$M$12,1,ROW()-16)-INDEX(ARUS_KAS!$B$13:$M$13,1,ROW()-16)-INDEX(ARUS_KAS!$B$14:$M$14,1,ROW()-16)-INDEX(ARUS_KAS!$B$15:$M$15,1,ROW()-16)+INDEX(ARUS_KAS!$B$24:$M$24,1,ROW()-16)-INDEX(ARUS_KAS!$B$25:$M$25,1,ROW()-16)+INDEX(ARUS_KAS!$B$26:$M$26,1,ROW()-16)+INDEX(ARUS_KAS!$B$28:$M$28,1,ROW()-16))} | N25: =IF(ROW()-16>MASTER!$AF$15,"",ABS(F25+G25-H25-I25-J25-K25+L25-M25))
A26: Okt | B26: =IF(ROW()-16>MASTER!$AF$15,"",SUMIFS(PEMASUKAN!$H$5:$H$204,PEMASUKAN!$C$5:$C$204,TEXT(DATE($B$4,ROW()-16,1),"yyyy-mm"),PEMASUKAN!$M$5:$M$204,"Pendapatan Operasional")) | C26: =IF(ROW()-16>MASTER!$AF$15,"",SUMIFS(PENGELUARAN!$K$5:$K$204,PENGELUARAN!$C$5:$C$204,TEXT(DATE($B$4,ROW()-16,1),"yyyy-mm"),PENGELUARAN!$L$5:$L$204,"Kantor")+SUMIFS(GAJI!$Q$5:$Q$124,GAJI!$B$5:$B$124,">="&DATE($B$4,ROW()-16,1),GAJI!$B$5:$B$124,"<"&DATE($B$4,ROW()-15,1))) | D26: =IF(ROW()-16>MASTER!$AF$15,"",B26-C26) | E26: =IF(ROW()-16>MASTER!$AF$15,"",SUM($D$17:D26)) | F26: =IF(ROW()-16>MASTER!$AF$15,"",IF(ROW()=17,SUMIFS(KAS_BANK!$B$5:$B$10,KAS_BANK!$A$5:$A$10,"<>Bank Dana Klien")+MAX(-KAS_BANK!$B$7,0)+MAX(-KAS_BANK!$B$8,0)+MAX(-KAS_BANK!$B$9,0),M25)) | G26: =IF(ROW()-16>MASTER!$AF$15,"",SUMIFS(PEMASUKAN!$J$5:$J$204,PEMASUKAN!$C$5:$C$204,TEXT(DATE($B$4,ROW()-16,1),"yyyy-mm"),PEMASUKAN!$M$5:$M$204,"Pendapatan Operasional")+SUMIFS(PEMASUKAN!$J$5:$J$204,PEMASUKAN!$C$5:$C$204,TEXT(DATE($B$4,ROW()-16,1),"yyyy-mm"),PEMASUKAN!$M$5:$M$204,"Penggantian Biaya")) | H26: =IF(ROW()-16>MASTER!$AF$15,"",SUMIFS(PENGELUARAN!$K$5:$K$204,PENGELUARAN!$C$5:$C$204,TEXT(DATE($B$4,ROW()-16,1),"yyyy-mm"),PENGELUARAN!$I$5:$I$204,"<>",PENGELUARAN!$I$5:$I$204,"<>Bank Dana Klien")+SUMIFS(GAJI!$P$5:$P$124,GAJI!$S$5:$S$124,">="&DATE($B$4,ROW()-16,1),GAJI!$S$5:$S$124,"<"&DATE($B$4,ROW()-15,1),GAJI!$R$5:$R$124,"Dibayar")+SUMIFS(KEWAJIBAN!$F$5:$F$124,KEWAJIBAN!$I$5:$I$124,">="&DATE($B$4,ROW()-16,1),KEWAJIBAN!$I$5:$I$124,"<"&DATE($B$4,ROW()-15,1))) | I26: =IF(ROW()-16>MASTER!$AF$15,"",SUMIFS(REIMBURSE!$J$5:$J$124,REIMBURSE!$N$5:$N$124,">="&DATE($B$4,ROW()-16,1),REIMBURSE!$N$5:$N$124,"<"&DATE($B$4,ROW()-15,1))) | J26: =IF(ROW()-16>MASTER!$AF$15,"",SUMIFS(PARTNER!$I$5:$I$124,PARTNER!$E$5:$E$124,MASTER!$Y$7,PARTNER!$V$5:$V$124,">="&DATE($B$4,ROW()-16,1),PARTNER!$V$5:$V$124,"<"&DATE($B$4,ROW()-15,1))+SUMIFS(PARTNER!$I$5:$I$124,PARTNER!$E$5:$E$124,MASTER!$Y$8,PARTNER!$V$5:$V$124,">="&DATE($B$4,ROW()-16,1),PARTNER!$V$5:$V$124,"<"&DATE($B$4,ROW()-15,1))) | K26: =IF(ROW()-16>MASTER!$AF$15,"",SUMIFS(PARTNER!$I$5:$I$124,PARTNER!$E$5:$E$124,MASTER!$Y$9,PARTNER!$V$5:$V$124,">="&DATE($B$4,ROW()-16,1),PARTNER!$V$5:$V$124,"<"&DATE($B$4,ROW()-15,1))) | L26: {=IF(ROW()-16>MASTER!$AF$15,"",INDEX(ARUS_KAS!$B$24:$M$24,1,ROW()-16)+INDEX(ARUS_KAS!$B$26:$M$26,1,ROW()-16)+INDEX(ARUS_KAS!$B$28:$M$28,1,ROW()-16))} | M26: {=IF(ROW()-16>MASTER!$AF$15,"",F26+INDEX(ARUS_KAS!$B$8:$M$8,1,ROW()-16)+INDEX(ARUS_KAS!$B$9:$M$9,1,ROW()-16)-INDEX(ARUS_KAS!$B$12:$M$12,1,ROW()-16)-INDEX(ARUS_KAS!$B$13:$M$13,1,ROW()-16)-INDEX(ARUS_KAS!$B$14:$M$14,1,ROW()-16)-INDEX(ARUS_KAS!$B$15:$M$15,1,ROW()-16)+INDEX(ARUS_KAS!$B$24:$M$24,1,ROW()-16)-INDEX(ARUS_KAS!$B$25:$M$25,1,ROW()-16)+INDEX(ARUS_KAS!$B$26:$M$26,1,ROW()-16)+INDEX(ARUS_KAS!$B$28:$M$28,1,ROW()-16))} | N26: =IF(ROW()-16>MASTER!$AF$15,"",ABS(F26+G26-H26-I26-J26-K26+L26-M26))
A27: Nov | B27: =IF(ROW()-16>MASTER!$AF$15,"",SUMIFS(PEMASUKAN!$H$5:$H$204,PEMASUKAN!$C$5:$C$204,TEXT(DATE($B$4,ROW()-16,1),"yyyy-mm"),PEMASUKAN!$M$5:$M$204,"Pendapatan Operasional")) | C27: =IF(ROW()-16>MASTER!$AF$15,"",SUMIFS(PENGELUARAN!$K$5:$K$204,PENGELUARAN!$C$5:$C$204,TEXT(DATE($B$4,ROW()-16,1),"yyyy-mm"),PENGELUARAN!$L$5:$L$204,"Kantor")+SUMIFS(GAJI!$Q$5:$Q$124,GAJI!$B$5:$B$124,">="&DATE($B$4,ROW()-16,1),GAJI!$B$5:$B$124,"<"&DATE($B$4,ROW()-15,1))) | D27: =IF(ROW()-16>MASTER!$AF$15,"",B27-C27) | E27: =IF(ROW()-16>MASTER!$AF$15,"",SUM($D$17:D27)) | F27: =IF(ROW()-16>MASTER!$AF$15,"",IF(ROW()=17,SUMIFS(KAS_BANK!$B$5:$B$10,KAS_BANK!$A$5:$A$10,"<>Bank Dana Klien")+MAX(-KAS_BANK!$B$7,0)+MAX(-KAS_BANK!$B$8,0)+MAX(-KAS_BANK!$B$9,0),M26)) | G27: =IF(ROW()-16>MASTER!$AF$15,"",SUMIFS(PEMASUKAN!$J$5:$J$204,PEMASUKAN!$C$5:$C$204,TEXT(DATE($B$4,ROW()-16,1),"yyyy-mm"),PEMASUKAN!$M$5:$M$204,"Pendapatan Operasional")+SUMIFS(PEMASUKAN!$J$5:$J$204,PEMASUKAN!$C$5:$C$204,TEXT(DATE($B$4,ROW()-16,1),"yyyy-mm"),PEMASUKAN!$M$5:$M$204,"Penggantian Biaya")) | H27: =IF(ROW()-16>MASTER!$AF$15,"",SUMIFS(PENGELUARAN!$K$5:$K$204,PENGELUARAN!$C$5:$C$204,TEXT(DATE($B$4,ROW()-16,1),"yyyy-mm"),PENGELUARAN!$I$5:$I$204,"<>",PENGELUARAN!$I$5:$I$204,"<>Bank Dana Klien")+SUMIFS(GAJI!$P$5:$P$124,GAJI!$S$5:$S$124,">="&DATE($B$4,ROW()-16,1),GAJI!$S$5:$S$124,"<"&DATE($B$4,ROW()-15,1),GAJI!$R$5:$R$124,"Dibayar")+SUMIFS(KEWAJIBAN!$F$5:$F$124,KEWAJIBAN!$I$5:$I$124,">="&DATE($B$4,ROW()-16,1),KEWAJIBAN!$I$5:$I$124,"<"&DATE($B$4,ROW()-15,1))) | I27: =IF(ROW()-16>MASTER!$AF$15,"",SUMIFS(REIMBURSE!$J$5:$J$124,REIMBURSE!$N$5:$N$124,">="&DATE($B$4,ROW()-16,1),REIMBURSE!$N$5:$N$124,"<"&DATE($B$4,ROW()-15,1))) | J27: =IF(ROW()-16>MASTER!$AF$15,"",SUMIFS(PARTNER!$I$5:$I$124,PARTNER!$E$5:$E$124,MASTER!$Y$7,PARTNER!$V$5:$V$124,">="&DATE($B$4,ROW()-16,1),PARTNER!$V$5:$V$124,"<"&DATE($B$4,ROW()-15,1))+SUMIFS(PARTNER!$I$5:$I$124,PARTNER!$E$5:$E$124,MASTER!$Y$8,PARTNER!$V$5:$V$124,">="&DATE($B$4,ROW()-16,1),PARTNER!$V$5:$V$124,"<"&DATE($B$4,ROW()-15,1))) | K27: =IF(ROW()-16>MASTER!$AF$15,"",SUMIFS(PARTNER!$I$5:$I$124,PARTNER!$E$5:$E$124,MASTER!$Y$9,PARTNER!$V$5:$V$124,">="&DATE($B$4,ROW()-16,1),PARTNER!$V$5:$V$124,"<"&DATE($B$4,ROW()-15,1))) | L27: {=IF(ROW()-16>MASTER!$AF$15,"",INDEX(ARUS_KAS!$B$24:$M$24,1,ROW()-16)+INDEX(ARUS_KAS!$B$26:$M$26,1,ROW()-16)+INDEX(ARUS_KAS!$B$28:$M$28,1,ROW()-16))} | M27: {=IF(ROW()-16>MASTER!$AF$15,"",F27+INDEX(ARUS_KAS!$B$8:$M$8,1,ROW()-16)+INDEX(ARUS_KAS!$B$9:$M$9,1,ROW()-16)-INDEX(ARUS_KAS!$B$12:$M$12,1,ROW()-16)-INDEX(ARUS_KAS!$B$13:$M$13,1,ROW()-16)-INDEX(ARUS_KAS!$B$14:$M$14,1,ROW()-16)-INDEX(ARUS_KAS!$B$15:$M$15,1,ROW()-16)+INDEX(ARUS_KAS!$B$24:$M$24,1,ROW()-16)-INDEX(ARUS_KAS!$B$25:$M$25,1,ROW()-16)+INDEX(ARUS_KAS!$B$26:$M$26,1,ROW()-16)+INDEX(ARUS_KAS!$B$28:$M$28,1,ROW()-16))} | N27: =IF(ROW()-16>MASTER!$AF$15,"",ABS(F27+G27-H27-I27-J27-K27+L27-M27))
A28: Des | B28: =IF(ROW()-16>MASTER!$AF$15,"",SUMIFS(PEMASUKAN!$H$5:$H$204,PEMASUKAN!$C$5:$C$204,TEXT(DATE($B$4,ROW()-16,1),"yyyy-mm"),PEMASUKAN!$M$5:$M$204,"Pendapatan Operasional")) | C28: =IF(ROW()-16>MASTER!$AF$15,"",SUMIFS(PENGELUARAN!$K$5:$K$204,PENGELUARAN!$C$5:$C$204,TEXT(DATE($B$4,ROW()-16,1),"yyyy-mm"),PENGELUARAN!$L$5:$L$204,"Kantor")+SUMIFS(GAJI!$Q$5:$Q$124,GAJI!$B$5:$B$124,">="&DATE($B$4,ROW()-16,1),GAJI!$B$5:$B$124,"<"&DATE($B$4,ROW()-15,1))) | D28: =IF(ROW()-16>MASTER!$AF$15,"",B28-C28) | E28: =IF(ROW()-16>MASTER!$AF$15,"",SUM($D$17:D28)) | F28: =IF(ROW()-16>MASTER!$AF$15,"",IF(ROW()=17,SUMIFS(KAS_BANK!$B$5:$B$10,KAS_BANK!$A$5:$A$10,"<>Bank Dana Klien")+MAX(-KAS_BANK!$B$7,0)+MAX(-KAS_BANK!$B$8,0)+MAX(-KAS_BANK!$B$9,0),M27)) | G28: =IF(ROW()-16>MASTER!$AF$15,"",SUMIFS(PEMASUKAN!$J$5:$J$204,PEMASUKAN!$C$5:$C$204,TEXT(DATE($B$4,ROW()-16,1),"yyyy-mm"),PEMASUKAN!$M$5:$M$204,"Pendapatan Operasional")+SUMIFS(PEMASUKAN!$J$5:$J$204,PEMASUKAN!$C$5:$C$204,TEXT(DATE($B$4,ROW()-16,1),"yyyy-mm"),PEMASUKAN!$M$5:$M$204,"Penggantian Biaya")) | H28: =IF(ROW()-16>MASTER!$AF$15,"",SUMIFS(PENGELUARAN!$K$5:$K$204,PENGELUARAN!$C$5:$C$204,TEXT(DATE($B$4,ROW()-16,1),"yyyy-mm"),PENGELUARAN!$I$5:$I$204,"<>",PENGELUARAN!$I$5:$I$204,"<>Bank Dana Klien")+SUMIFS(GAJI!$P$5:$P$124,GAJI!$S$5:$S$124,">="&DATE($B$4,ROW()-16,1),GAJI!$S$5:$S$124,"<"&DATE($B$4,ROW()-15,1),GAJI!$R$5:$R$124,"Dibayar")+SUMIFS(KEWAJIBAN!$F$5:$F$124,KEWAJIBAN!$I$5:$I$124,">="&DATE($B$4,ROW()-16,1),KEWAJIBAN!$I$5:$I$124,"<"&DATE($B$4,ROW()-15,1))) | I28: =IF(ROW()-16>MASTER!$AF$15,"",SUMIFS(REIMBURSE!$J$5:$J$124,REIMBURSE!$N$5:$N$124,">="&DATE($B$4,ROW()-16,1),REIMBURSE!$N$5:$N$124,"<"&DATE($B$4,ROW()-15,1))) | J28: =IF(ROW()-16>MASTER!$AF$15,"",SUMIFS(PARTNER!$I$5:$I$124,PARTNER!$E$5:$E$124,MASTER!$Y$7,PARTNER!$V$5:$V$124,">="&DATE($B$4,ROW()-16,1),PARTNER!$V$5:$V$124,"<"&DATE($B$4,ROW()-15,1))+SUMIFS(PARTNER!$I$5:$I$124,PARTNER!$E$5:$E$124,MASTER!$Y$8,PARTNER!$V$5:$V$124,">="&DATE($B$4,ROW()-16,1),PARTNER!$V$5:$V$124,"<"&DATE($B$4,ROW()-15,1))) | K28: =IF(ROW()-16>MASTER!$AF$15,"",SUMIFS(PARTNER!$I$5:$I$124,PARTNER!$E$5:$E$124,MASTER!$Y$9,PARTNER!$V$5:$V$124,">="&DATE($B$4,ROW()-16,1),PARTNER!$V$5:$V$124,"<"&DATE($B$4,ROW()-15,1))) | L28: {=IF(ROW()-16>MASTER!$AF$15,"",INDEX(ARUS_KAS!$B$24:$M$24,1,ROW()-16)+INDEX(ARUS_KAS!$B$26:$M$26,1,ROW()-16)+INDEX(ARUS_KAS!$B$28:$M$28,1,ROW()-16))} | M28: {=IF(ROW()-16>MASTER!$AF$15,"",F28+INDEX(ARUS_KAS!$B$8:$M$8,1,ROW()-16)+INDEX(ARUS_KAS!$B$9:$M$9,1,ROW()-16)-INDEX(ARUS_KAS!$B$12:$M$12,1,ROW()-16)-INDEX(ARUS_KAS!$B$13:$M$13,1,ROW()-16)-INDEX(ARUS_KAS!$B$14:$M$14,1,ROW()-16)-INDEX(ARUS_KAS!$B$15:$M$15,1,ROW()-16)+INDEX(ARUS_KAS!$B$24:$M$24,1,ROW()-16)-INDEX(ARUS_KAS!$B$25:$M$25,1,ROW()-16)+INDEX(ARUS_KAS!$B$26:$M$26,1,ROW()-16)+INDEX(ARUS_KAS!$B$28:$M$28,1,ROW()-16))} | N28: =IF(ROW()-16>MASTER!$AF$15,"",ABS(F28+G28-H28-I28-J28-K28+L28-M28))
A29: TOTAL / AKHIR | B29: =SUM(B17:B28) -> 16000000 | C29: =SUM(C17:C28) -> 8095908 | D29: =SUM(D17:D28) -> 7904092 | E29: {=IFERROR(INDEX(E17:E28,MASTER!$AF$15),0)} -> 7904092 | F29: {=IFERROR(INDEX(F17:F28,MASTER!$AF$15),"")} -> 4609400 | G29: =SUM(G17:G28) -> 16000000 | H29: =SUM(H17:H28) -> 5095908 | I29: =SUM(I17:I28) -> 0 | J29: =SUM(J17:J28) -> 9000000 | K29: =SUM(K17:K28) -> 0 | L29: =SUM(L17:L28) -> 1000000 | M29: {=IFERROR(INDEX(M17:M28,MASTER!$AF$15),0)} -> 2904092 | N29: =SUM(N17:N28) -> 0
A31: Kas awal berasal dari saldo bulan sebelumnya dan BUKAN pendapatan. Pembagian laba / prive mengurangi kas serta ekuitas. Pengembalian talangan mengurangi kas serta utang partner. Pendanaan / mutasi lain mencakup modal, pinjaman, talangan baru, dan perpindahan dana. | B31: Kas awal berasal dari saldo bulan sebelumnya dan BUKAN pendapatan. Pembagian laba / prive mengurangi kas serta ekuitas. Pengembalian talangan mengurangi kas serta utang partner. Pendanaan / mutasi lain mencakup modal, pinjaman, talangan baru, dan perpindahan dana. | C31: Kas awal berasal dari saldo bulan sebelumnya dan BUKAN pendapatan. Pembagian laba / prive mengurangi kas serta ekuitas. Pengembalian talangan mengurangi kas serta utang partner. Pendanaan / mutasi lain mencakup modal, pinjaman, talangan baru, dan perpindahan dana. | D31: Kas awal berasal dari saldo bulan sebelumnya dan BUKAN pendapatan. Pembagian laba / prive mengurangi kas serta ekuitas. Pengembalian talangan mengurangi kas serta utang partner. Pendanaan / mutasi lain mencakup modal, pinjaman, talangan baru, dan perpindahan dana. | E31: Kas awal berasal dari saldo bulan sebelumnya dan BUKAN pendapatan. Pembagian laba / prive mengurangi kas serta ekuitas. Pengembalian talangan mengurangi kas serta utang partner. Pendanaan / mutasi lain mencakup modal, pinjaman, talangan baru, dan perpindahan dana. | F31: Kas awal berasal dari saldo bulan sebelumnya dan BUKAN pendapatan. Pembagian laba / prive mengurangi kas serta ekuitas. Pengembalian talangan mengurangi kas serta utang partner. Pendanaan / mutasi lain mencakup modal, pinjaman, talangan baru, dan perpindahan dana. | G31: Kas awal berasal dari saldo bulan sebelumnya dan BUKAN pendapatan. Pembagian laba / prive mengurangi kas serta ekuitas. Pengembalian talangan mengurangi kas serta utang partner. Pendanaan / mutasi lain mencakup modal, pinjaman, talangan baru, dan perpindahan dana. | H31: Kas awal berasal dari saldo bulan sebelumnya dan BUKAN pendapatan. Pembagian laba / prive mengurangi kas serta ekuitas. Pengembalian talangan mengurangi kas serta utang partner. Pendanaan / mutasi lain mencakup modal, pinjaman, talangan baru, dan perpindahan dana. | I31: Kas awal berasal dari saldo bulan sebelumnya dan BUKAN pendapatan. Pembagian laba / prive mengurangi kas serta ekuitas. Pengembalian talangan mengurangi kas serta utang partner. Pendanaan / mutasi lain mencakup modal, pinjaman, talangan baru, dan perpindahan dana. | J31: Kas awal berasal dari saldo bulan sebelumnya dan BUKAN pendapatan. Pembagian laba / prive mengurangi kas serta ekuitas. Pengembalian talangan mengurangi kas serta utang partner. Pendanaan / mutasi lain mencakup modal, pinjaman, talangan baru, dan perpindahan dana. | K31: Kas awal berasal dari saldo bulan sebelumnya dan BUKAN pendapatan. Pembagian laba / prive mengurangi kas serta ekuitas. Pengembalian talangan mengurangi kas serta utang partner. Pendanaan / mutasi lain mencakup modal, pinjaman, talangan baru, dan perpindahan dana. | L31: Kas awal berasal dari saldo bulan sebelumnya dan BUKAN pendapatan. Pembagian laba / prive mengurangi kas serta ekuitas. Pengembalian talangan mengurangi kas serta utang partner. Pendanaan / mutasi lain mencakup modal, pinjaman, talangan baru, dan perpindahan dana. | M31: Kas awal berasal dari saldo bulan sebelumnya dan BUKAN pendapatan. Pembagian laba / prive mengurangi kas serta ekuitas. Pengembalian talangan mengurangi kas serta utang partner. Pendanaan / mutasi lain mencakup modal, pinjaman, talangan baru, dan perpindahan dana. | N31: Kas awal berasal dari saldo bulan sebelumnya dan BUKAN pendapatan. Pembagian laba / prive mengurangi kas serta ekuitas. Pengembalian talangan mengurangi kas serta utang partner. Pendanaan / mutasi lain mencakup modal, pinjaman, talangan baru, dan perpindahan dana.
A33: RINCIAN ARUS KAS BULAN YANG DIPILIH | B33: RINCIAN ARUS KAS BULAN YANG DIPILIH | C33: RINCIAN ARUS KAS BULAN YANG DIPILIH | D33: RINCIAN ARUS KAS BULAN YANG DIPILIH | E33: RINCIAN ARUS KAS BULAN YANG DIPILIH | F33: RINCIAN ARUS KAS BULAN YANG DIPILIH | G33: RINCIAN ARUS KAS BULAN YANG DIPILIH | H33: LABA, EKUITAS, DAN KONTROL BULAN TERPILIH | I33: LABA, EKUITAS, DAN KONTROL BULAN TERPILIH | J33: LABA, EKUITAS, DAN KONTROL BULAN TERPILIH | K33: LABA, EKUITAS, DAN KONTROL BULAN TERPILIH | L33: LABA, EKUITAS, DAN KONTROL BULAN TERPILIH | M33: LABA, EKUITAS, DAN KONTROL BULAN TERPILIH | N33: LABA, EKUITAS, DAN KONTROL BULAN TERPILIH
A35: Saldo awal dari bulan sebelumnya | B35: Saldo awal dari bulan sebelumnya | C35: Saldo awal dari bulan sebelumnya | D35: Saldo awal dari bulan sebelumnya | E35: =INDEX($F$17:$F$28,MASTER!$AF$15) -> 4609400 | H35: Laba / rugi bulan berjalan | I35: Laba / rugi bulan berjalan | J35: Laba / rugi bulan berjalan | K35: Laba / rugi bulan berjalan | L35: =INDEX($D$17:$D$28,MASTER!$AF$15) -> -4705308
A36: (+) Kas masuk operasional | B36: (+) Kas masuk operasional | C36: (+) Kas masuk operasional | D36: (+) Kas masuk operasional | E36: =INDEX($G$17:$G$28,MASTER!$AF$15) -> 0 | H36: Laba usaha kumulatif | I36: Laba usaha kumulatif | J36: Laba usaha kumulatif | K36: Laba usaha kumulatif | L36: =INDEX($E$17:$E$28,MASTER!$AF$15) -> 7904092
A37: (-) Biaya, gaji, dan kewajiban | B37: (-) Biaya, gaji, dan kewajiban | C37: (-) Biaya, gaji, dan kewajiban | D37: (-) Biaya, gaji, dan kewajiban | E37: =INDEX($H$17:$H$28,MASTER!$AF$15) -> 1705308 | H37: Pembagian partner bulan ini | I37: Pembagian partner bulan ini | J37: Pembagian partner bulan ini | K37: Pembagian partner bulan ini | L37: =INDEX($J$17:$J$28,MASTER!$AF$15) -> 0
A38: (-) Reimburse dibayarkan | B38: (-) Reimburse dibayarkan | C38: (-) Reimburse dibayarkan | D38: (-) Reimburse dibayarkan | E38: =INDEX($I$17:$I$28,MASTER!$AF$15) -> 0 | H38: Utang / talangan partner berjalan | I38: Utang / talangan partner berjalan | J38: Utang / talangan partner berjalan | K38: Utang / talangan partner berjalan | L38: =TALANGAN_PARTNER!I9 -> 1000000
A39: (-) Pembagian partner / prive | B39: (-) Pembagian partner / prive | C39: (-) Pembagian partner / prive | D39: (-) Pembagian partner / prive | E39: =INDEX($J$17:$J$28,MASTER!$AF$15) -> 0 | H39: Ekuitas setelah pembagian | I39: Ekuitas setelah pembagian | J39: Ekuitas setelah pembagian | K39: Ekuitas setelah pembagian | L39: =EKUITAS!N8 -> -9000000
A40: (-) Pengembalian talangan partner | B40: (-) Pengembalian talangan partner | C40: (-) Pengembalian talangan partner | D40: (-) Pengembalian talangan partner | E40: =INDEX($K$17:$K$28,MASTER!$AF$15) -> 0 | H40: Piutang klien belum dibayar | I40: Piutang klien belum dibayar | J40: Piutang klien belum dibayar | K40: Piutang klien belum dibayar | L40: =SUM(INVOICE_PIUTANG!$L$5:$L$151) -> 33500000
A41: (+/-) Pendanaan dan mutasi lain | B41: (+/-) Pendanaan dan mutasi lain | C41: (+/-) Pendanaan dan mutasi lain | D41: (+/-) Pendanaan dan mutasi lain | E41: =INDEX($L$17:$L$28,MASTER!$AF$15) -> 0 | H41: Selisih jembatan kas bulan ini | I41: Selisih jembatan kas bulan ini | J41: Selisih jembatan kas bulan ini | K41: Selisih jembatan kas bulan ini | L41: =INDEX($N$17:$N$28,MASTER!$AF$15) -> 0
A42: SALDO KAS AKHIR BULAN | B42: SALDO KAS AKHIR BULAN | C42: SALDO KAS AKHIR BULAN | D42: SALDO KAS AKHIR BULAN | E42: =INDEX($M$17:$M$28,MASTER!$AF$15) -> 2904092 | H42: STATUS MODEL KEUANGAN | I42: STATUS MODEL KEUANGAN | J42: STATUS MODEL KEUANGAN | K42: STATUS MODEL KEUANGAN | L42: =KONTROL!A68 -> PERIKSA — ADA TEMUAN KRITIS / TINGGI
A44: RINGKASAN PARTNER — PEMBAGIAN LABA, REIMBURSE, DAN TALANGAN | B44: RINGKASAN PARTNER — PEMBAGIAN LABA, REIMBURSE, DAN TALANGAN | C44: RINGKASAN PARTNER — PEMBAGIAN LABA, REIMBURSE, DAN TALANGAN | D44: RINGKASAN PARTNER — PEMBAGIAN LABA, REIMBURSE, DAN TALANGAN | E44: RINGKASAN PARTNER — PEMBAGIAN LABA, REIMBURSE, DAN TALANGAN | F44: RINGKASAN PARTNER — PEMBAGIAN LABA, REIMBURSE, DAN TALANGAN | G44: RINGKASAN PARTNER — PEMBAGIAN LABA, REIMBURSE, DAN TALANGAN | H44: RINGKASAN PARTNER — PEMBAGIAN LABA, REIMBURSE, DAN TALANGAN | I44: RINGKASAN PARTNER — PEMBAGIAN LABA, REIMBURSE, DAN TALANGAN | J44: RINGKASAN PARTNER — PEMBAGIAN LABA, REIMBURSE, DAN TALANGAN | K44: RINGKASAN PARTNER — PEMBAGIAN LABA, REIMBURSE, DAN TALANGAN | L44: RINGKASAN PARTNER — PEMBAGIAN LABA, REIMBURSE, DAN TALANGAN | M44: RINGKASAN PARTNER — PEMBAGIAN LABA, REIMBURSE, DAN TALANGAN | N44: RINGKASAN PARTNER — PEMBAGIAN LABA, REIMBURSE, DAN TALANGAN
A45: Partner | B45: Partner | C45: Alokasi Hak / Laba | D45: Alokasi Hak / Laba | E45: Prive / Bagi Hasil | F45: Prive / Bagi Hasil | G45: Pengembalian Talangan | H45: Pengembalian Talangan | I45: Reimburse Dibayar | J45: Reimburse Dibayar | K45: Utang Talangan Tersisa | L45: Utang Talangan Tersisa | M45: Saldo Hak Partner | N45: Saldo Hak Partner
A46: =MASTER!A5 -> Fajar Roni | C46: =SUMIFS(PARTNER!$H$5:$H$124,PARTNER!$D$5:$D$124,$A46,PARTNER!$E$5:$E$124,MASTER!$Y$6) -> 0 | E46: =SUMIFS(PARTNER!$I$5:$I$124,PARTNER!$D$5:$D$124,$A46,PARTNER!$E$5:$E$124,MASTER!$Y$7)+SUMIFS(PARTNER!$I$5:$I$124,PARTNER!$D$5:$D$124,$A46,PARTNER!$E$5:$E$124,MASTER!$Y$8) -> 9000000 | G46: =SUMIFS(PARTNER!$I$5:$I$124,PARTNER!$D$5:$D$124,$A46,PARTNER!$E$5:$E$124,MASTER!$Y$9) -> 0 | I46: =SUMIFS(REIMBURSE!$J$5:$J$124,REIMBURSE!$C$5:$C$124,$A46) -> 0 | K46: =SUMIFS(TALANGAN_PARTNER!$I$6:$I$8,TALANGAN_PARTNER!$A$6:$A$8,$A46) -> 1000000 | M46: =SUMIFS(PARTNER!$H$5:$H$124,PARTNER!$D$5:$D$124,$A46)-SUMIFS(PARTNER!$I$5:$I$124,PARTNER!$D$5:$D$124,$A46)+SUMIFS(PARTNER!$I$5:$I$124,PARTNER!$D$5:$D$124,$A46,PARTNER!$E$5:$E$124,MASTER!$Y$9) -> 0
A47: =MASTER!A6 -> Reza Evaldo Kusumah | C47: =SUMIFS(PARTNER!$H$5:$H$124,PARTNER!$D$5:$D$124,$A47,PARTNER!$E$5:$E$124,MASTER!$Y$6) -> 0 | E47: =SUMIFS(PARTNER!$I$5:$I$124,PARTNER!$D$5:$D$124,$A47,PARTNER!$E$5:$E$124,MASTER!$Y$7)+SUMIFS(PARTNER!$I$5:$I$124,PARTNER!$D$5:$D$124,$A47,PARTNER!$E$5:$E$124,MASTER!$Y$8) -> 0 | G47: =SUMIFS(PARTNER!$I$5:$I$124,PARTNER!$D$5:$D$124,$A47,PARTNER!$E$5:$E$124,MASTER!$Y$9) -> 0 | I47: =SUMIFS(REIMBURSE!$J$5:$J$124,REIMBURSE!$C$5:$C$124,$A47) -> 0 | K47: =SUMIFS(TALANGAN_PARTNER!$I$6:$I$8,TALANGAN_PARTNER!$A$6:$A$8,$A47) -> 0 | M47: =SUMIFS(PARTNER!$H$5:$H$124,PARTNER!$D$5:$D$124,$A47)-SUMIFS(PARTNER!$I$5:$I$124,PARTNER!$D$5:$D$124,$A47)+SUMIFS(PARTNER!$I$5:$I$124,PARTNER!$D$5:$D$124,$A47,PARTNER!$E$5:$E$124,MASTER!$Y$9) -> 0
